2019-01-20 09:44:30,242 - [logs/pythonClickhouse.log:16]=> logs/pythonClickhouse.log
2019-01-20 09:44:30,766 - [logs/pythonClickhouse.log:80]=> load data start_date:2018-05-02 00:00:00
2019-01-20 09:44:30,767 - [logs/pythonClickhouse.log:81]=> load_data  to_date:2018-05-17 00:00:00
2019-01-20 09:44:30,767 - [logs/pythonClickhouse.log:74]=> query:SELECT block_timestamp,difficulty,block_nrg_consumed,nrg_limit,num_transactions,block_size,block_time,approx_nrg_reward,from_addr,to_addr,approx_value,transaction_nrg_consumed,nrg_price FROM aion.block_tx_warehouse WHERE toDate(block_timestamp) >= toDate('2018-05-02 00:00:00') AND 
               toDate(block_timestamp) <= toDate('2018-05-17 00:00:00') ORDER BY block_timestamp
2019-01-20 09:44:30,928 - [logs/pythonClickhouse.log:103]=> DATA SUCCESSFULLY LOADED FROM CLICKHOUSE:0
2019-01-20 09:44:35,975 - [logs/pythonClickhouse.log:80]=> load data start_date:2018-05-10 00:00:00
2019-01-20 09:44:35,975 - [logs/pythonClickhouse.log:81]=> load_data  to_date:2018-05-11 00:00:00
2019-01-20 09:44:35,976 - [logs/pythonClickhouse.log:74]=> query:SELECT block_timestamp,difficulty,block_nrg_consumed,nrg_limit,num_transactions,block_size,block_time,approx_nrg_reward,from_addr,to_addr,approx_value,transaction_nrg_consumed,nrg_price FROM aion.block_tx_warehouse WHERE toDate(block_timestamp) >= toDate('2018-05-10 00:00:00') AND 
               toDate(block_timestamp) <= toDate('2018-05-11 00:00:00') ORDER BY block_timestamp
2019-01-20 09:44:36,121 - [logs/pythonClickhouse.log:103]=> DATA SUCCESSFULLY LOADED FROM CLICKHOUSE:0
2019-01-20 09:44:41,149 - [logs/pythonClickhouse.log:80]=> load data start_date:2018-05-11 00:00:00
2019-01-20 09:44:41,150 - [logs/pythonClickhouse.log:81]=> load_data  to_date:2018-05-12 00:00:00
2019-01-20 09:44:41,150 - [logs/pythonClickhouse.log:74]=> query:SELECT block_timestamp,difficulty,block_nrg_consumed,nrg_limit,num_transactions,block_size,block_time,approx_nrg_reward,from_addr,to_addr,approx_value,transaction_nrg_consumed,nrg_price FROM aion.block_tx_warehouse WHERE toDate(block_timestamp) >= toDate('2018-05-11 00:00:00') AND 
               toDate(block_timestamp) <= toDate('2018-05-12 00:00:00') ORDER BY block_timestamp
2019-01-20 09:44:41,288 - [logs/pythonClickhouse.log:103]=> DATA SUCCESSFULLY LOADED FROM CLICKHOUSE:0
2019-01-20 09:44:46,311 - [logs/pythonClickhouse.log:80]=> load data start_date:2018-05-12 00:00:00
2019-01-20 09:44:46,312 - [logs/pythonClickhouse.log:81]=> load_data  to_date:2018-05-13 00:00:00
2019-01-20 09:44:46,312 - [logs/pythonClickhouse.log:74]=> query:SELECT block_timestamp,difficulty,block_nrg_consumed,nrg_limit,num_transactions,block_size,block_time,approx_nrg_reward,from_addr,to_addr,approx_value,transaction_nrg_consumed,nrg_price FROM aion.block_tx_warehouse WHERE toDate(block_timestamp) >= toDate('2018-05-12 00:00:00') AND 
               toDate(block_timestamp) <= toDate('2018-05-13 00:00:00') ORDER BY block_timestamp
2019-01-20 09:44:46,433 - [logs/pythonClickhouse.log:103]=> DATA SUCCESSFULLY LOADED FROM CLICKHOUSE:0
2019-01-20 09:44:51,461 - [logs/pythonClickhouse.log:80]=> load data start_date:2018-05-13 00:00:00
2019-01-20 09:44:51,461 - [logs/pythonClickhouse.log:81]=> load_data  to_date:2018-05-14 00:00:00
2019-01-20 09:44:51,462 - [logs/pythonClickhouse.log:74]=> query:SELECT block_timestamp,difficulty,block_nrg_consumed,nrg_limit,num_transactions,block_size,block_time,approx_nrg_reward,from_addr,to_addr,approx_value,transaction_nrg_consumed,nrg_price FROM aion.block_tx_warehouse WHERE toDate(block_timestamp) >= toDate('2018-05-13 00:00:00') AND 
               toDate(block_timestamp) <= toDate('2018-05-14 00:00:00') ORDER BY block_timestamp
2019-01-20 09:44:51,598 - [logs/pythonClickhouse.log:103]=> DATA SUCCESSFULLY LOADED FROM CLICKHOUSE:0
2019-01-20 09:44:56,623 - [logs/pythonClickhouse.log:80]=> load data start_date:2018-05-14 00:00:00
2019-01-20 09:44:56,623 - [logs/pythonClickhouse.log:81]=> load_data  to_date:2018-05-15 00:00:00
2019-01-20 09:44:56,624 - [logs/pythonClickhouse.log:74]=> query:SELECT block_timestamp,difficulty,block_nrg_consumed,nrg_limit,num_transactions,block_size,block_time,approx_nrg_reward,from_addr,to_addr,approx_value,transaction_nrg_consumed,nrg_price FROM aion.block_tx_warehouse WHERE toDate(block_timestamp) >= toDate('2018-05-14 00:00:00') AND 
               toDate(block_timestamp) <= toDate('2018-05-15 00:00:00') ORDER BY block_timestamp
2019-01-20 09:44:56,746 - [logs/pythonClickhouse.log:103]=> DATA SUCCESSFULLY LOADED FROM CLICKHOUSE:0
2019-01-20 09:45:01,770 - [logs/pythonClickhouse.log:80]=> load data start_date:2018-05-15 00:00:00
2019-01-20 09:45:01,770 - [logs/pythonClickhouse.log:81]=> load_data  to_date:2018-05-16 00:00:00
2019-01-20 09:45:01,771 - [logs/pythonClickhouse.log:74]=> query:SELECT block_timestamp,difficulty,block_nrg_consumed,nrg_limit,num_transactions,block_size,block_time,approx_nrg_reward,from_addr,to_addr,approx_value,transaction_nrg_consumed,nrg_price FROM aion.block_tx_warehouse WHERE toDate(block_timestamp) >= toDate('2018-05-15 00:00:00') AND 
               toDate(block_timestamp) <= toDate('2018-05-16 00:00:00') ORDER BY block_timestamp
2019-01-20 09:45:01,911 - [logs/pythonClickhouse.log:103]=> DATA SUCCESSFULLY LOADED FROM CLICKHOUSE:0
2019-01-20 09:45:06,935 - [logs/pythonClickhouse.log:80]=> load data start_date:2018-05-16 00:00:00
2019-01-20 09:45:06,935 - [logs/pythonClickhouse.log:81]=> load_data  to_date:2018-05-17 00:00:00
2019-01-20 09:45:06,935 - [logs/pythonClickhouse.log:74]=> query:SELECT block_timestamp,difficulty,block_nrg_consumed,nrg_limit,num_transactions,block_size,block_time,approx_nrg_reward,from_addr,to_addr,approx_value,transaction_nrg_consumed,nrg_price FROM aion.block_tx_warehouse WHERE toDate(block_timestamp) >= toDate('2018-05-16 00:00:00') AND 
               toDate(block_timestamp) <= toDate('2018-05-17 00:00:00') ORDER BY block_timestamp
2019-01-20 09:45:07,031 - [logs/pythonClickhouse.log:103]=> DATA SUCCESSFULLY LOADED FROM CLICKHOUSE:0
2019-01-20 09:45:12,057 - [logs/pythonClickhouse.log:80]=> load data start_date:2018-05-17 00:00:00
2019-01-20 09:45:12,057 - [logs/pythonClickhouse.log:81]=> load_data  to_date:2018-05-18 00:00:00
2019-01-20 09:45:12,057 - [logs/pythonClickhouse.log:74]=> query:SELECT block_timestamp,difficulty,block_nrg_consumed,nrg_limit,num_transactions,block_size,block_time,approx_nrg_reward,from_addr,to_addr,approx_value,transaction_nrg_consumed,nrg_price FROM aion.block_tx_warehouse WHERE toDate(block_timestamp) >= toDate('2018-05-17 00:00:00') AND 
               toDate(block_timestamp) <= toDate('2018-05-18 00:00:00') ORDER BY block_timestamp
2019-01-20 09:45:12,171 - [logs/pythonClickhouse.log:103]=> DATA SUCCESSFULLY LOADED FROM CLICKHOUSE:0
2019-01-20 09:45:17,197 - [logs/pythonClickhouse.log:80]=> load data start_date:2018-05-18 00:00:00
2019-01-20 09:45:17,198 - [logs/pythonClickhouse.log:81]=> load_data  to_date:2018-05-19 00:00:00
2019-01-20 09:45:17,198 - [logs/pythonClickhouse.log:74]=> query:SELECT block_timestamp,difficulty,block_nrg_consumed,nrg_limit,num_transactions,block_size,block_time,approx_nrg_reward,from_addr,to_addr,approx_value,transaction_nrg_consumed,nrg_price FROM aion.block_tx_warehouse WHERE toDate(block_timestamp) >= toDate('2018-05-18 00:00:00') AND 
               toDate(block_timestamp) <= toDate('2018-05-19 00:00:00') ORDER BY block_timestamp
2019-01-20 09:45:17,321 - [logs/pythonClickhouse.log:103]=> DATA SUCCESSFULLY LOADED FROM CLICKHOUSE:0
2019-01-20 09:45:22,344 - [logs/pythonClickhouse.log:80]=> load data start_date:2018-05-19 00:00:00
2019-01-20 09:45:22,344 - [logs/pythonClickhouse.log:81]=> load_data  to_date:2018-05-20 00:00:00
2019-01-20 09:45:22,345 - [logs/pythonClickhouse.log:74]=> query:SELECT block_timestamp,difficulty,block_nrg_consumed,nrg_limit,num_transactions,block_size,block_time,approx_nrg_reward,from_addr,to_addr,approx_value,transaction_nrg_consumed,nrg_price FROM aion.block_tx_warehouse WHERE toDate(block_timestamp) >= toDate('2018-05-19 00:00:00') AND 
               toDate(block_timestamp) <= toDate('2018-05-20 00:00:00') ORDER BY block_timestamp
2019-01-20 09:45:22,465 - [logs/pythonClickhouse.log:103]=> DATA SUCCESSFULLY LOADED FROM CLICKHOUSE:0
2019-01-20 09:45:27,493 - [logs/pythonClickhouse.log:80]=> load data start_date:2018-05-20 00:00:00
2019-01-20 09:45:27,493 - [logs/pythonClickhouse.log:81]=> load_data  to_date:2018-05-21 00:00:00
2019-01-20 09:45:27,494 - [logs/pythonClickhouse.log:74]=> query:SELECT block_timestamp,difficulty,block_nrg_consumed,nrg_limit,num_transactions,block_size,block_time,approx_nrg_reward,from_addr,to_addr,approx_value,transaction_nrg_consumed,nrg_price FROM aion.block_tx_warehouse WHERE toDate(block_timestamp) >= toDate('2018-05-20 00:00:00') AND 
               toDate(block_timestamp) <= toDate('2018-05-21 00:00:00') ORDER BY block_timestamp
2019-01-20 09:45:27,745 - [logs/pythonClickhouse.log:103]=> DATA SUCCESSFULLY LOADED FROM CLICKHOUSE:9976
2019-01-20 09:45:52,471 - [logs/pythonClickhouse.log:16]=> logs/pythonClickhouse.log
2019-01-20 09:45:53,178 - [logs/pythonClickhouse.log:80]=> load data start_date:2018-05-02 00:00:00
2019-01-20 09:45:53,178 - [logs/pythonClickhouse.log:81]=> load_data  to_date:2018-05-17 00:00:00
2019-01-20 09:45:53,179 - [logs/pythonClickhouse.log:74]=> query:SELECT block_timestamp,difficulty,block_nrg_consumed,nrg_limit,num_transactions,block_size,block_time,approx_nrg_reward,from_addr,to_addr,approx_value,transaction_nrg_consumed,nrg_price FROM aion.block_tx_warehouse WHERE toDate(block_timestamp) >= toDate('2018-05-02 00:00:00') AND 
               toDate(block_timestamp) <= toDate('2018-05-17 00:00:00') ORDER BY block_timestamp
2019-01-20 09:45:53,336 - [logs/pythonClickhouse.log:103]=> DATA SUCCESSFULLY LOADED FROM CLICKHOUSE:0
2019-01-20 09:45:58,384 - [logs/pythonClickhouse.log:80]=> load data start_date:2018-05-10 00:00:00
2019-01-20 09:45:58,384 - [logs/pythonClickhouse.log:81]=> load_data  to_date:2018-05-11 00:00:00
2019-01-20 09:45:58,385 - [logs/pythonClickhouse.log:74]=> query:SELECT block_timestamp,difficulty,block_nrg_consumed,nrg_limit,num_transactions,block_size,block_time,approx_nrg_reward,from_addr,to_addr,approx_value,transaction_nrg_consumed,nrg_price FROM aion.block_tx_warehouse WHERE toDate(block_timestamp) >= toDate('2018-05-10 00:00:00') AND 
               toDate(block_timestamp) <= toDate('2018-05-11 00:00:00') ORDER BY block_timestamp
2019-01-20 09:45:58,508 - [logs/pythonClickhouse.log:103]=> DATA SUCCESSFULLY LOADED FROM CLICKHOUSE:0
2019-01-20 09:46:03,536 - [logs/pythonClickhouse.log:80]=> load data start_date:2018-05-11 00:00:00
2019-01-20 09:46:03,536 - [logs/pythonClickhouse.log:81]=> load_data  to_date:2018-05-12 00:00:00
2019-01-20 09:46:03,537 - [logs/pythonClickhouse.log:74]=> query:SELECT block_timestamp,difficulty,block_nrg_consumed,nrg_limit,num_transactions,block_size,block_time,approx_nrg_reward,from_addr,to_addr,approx_value,transaction_nrg_consumed,nrg_price FROM aion.block_tx_warehouse WHERE toDate(block_timestamp) >= toDate('2018-05-11 00:00:00') AND 
               toDate(block_timestamp) <= toDate('2018-05-12 00:00:00') ORDER BY block_timestamp
2019-01-20 09:46:03,672 - [logs/pythonClickhouse.log:103]=> DATA SUCCESSFULLY LOADED FROM CLICKHOUSE:0
2019-01-20 09:46:08,698 - [logs/pythonClickhouse.log:80]=> load data start_date:2018-05-12 00:00:00
2019-01-20 09:46:08,698 - [logs/pythonClickhouse.log:81]=> load_data  to_date:2018-05-13 00:00:00
2019-01-20 09:46:08,699 - [logs/pythonClickhouse.log:74]=> query:SELECT block_timestamp,difficulty,block_nrg_consumed,nrg_limit,num_transactions,block_size,block_time,approx_nrg_reward,from_addr,to_addr,approx_value,transaction_nrg_consumed,nrg_price FROM aion.block_tx_warehouse WHERE toDate(block_timestamp) >= toDate('2018-05-12 00:00:00') AND 
               toDate(block_timestamp) <= toDate('2018-05-13 00:00:00') ORDER BY block_timestamp
2019-01-20 09:46:08,830 - [logs/pythonClickhouse.log:103]=> DATA SUCCESSFULLY LOADED FROM CLICKHOUSE:0
2019-01-20 09:46:13,858 - [logs/pythonClickhouse.log:80]=> load data start_date:2018-05-13 00:00:00
2019-01-20 09:46:13,859 - [logs/pythonClickhouse.log:81]=> load_data  to_date:2018-05-14 00:00:00
2019-01-20 09:46:13,860 - [logs/pythonClickhouse.log:74]=> query:SELECT block_timestamp,difficulty,block_nrg_consumed,nrg_limit,num_transactions,block_size,block_time,approx_nrg_reward,from_addr,to_addr,approx_value,transaction_nrg_consumed,nrg_price FROM aion.block_tx_warehouse WHERE toDate(block_timestamp) >= toDate('2018-05-13 00:00:00') AND 
               toDate(block_timestamp) <= toDate('2018-05-14 00:00:00') ORDER BY block_timestamp
2019-01-20 09:46:13,999 - [logs/pythonClickhouse.log:103]=> DATA SUCCESSFULLY LOADED FROM CLICKHOUSE:0
2019-01-20 09:46:19,022 - [logs/pythonClickhouse.log:80]=> load data start_date:2018-05-14 00:00:00
2019-01-20 09:46:19,022 - [logs/pythonClickhouse.log:81]=> load_data  to_date:2018-05-15 00:00:00
2019-01-20 09:46:19,023 - [logs/pythonClickhouse.log:74]=> query:SELECT block_timestamp,difficulty,block_nrg_consumed,nrg_limit,num_transactions,block_size,block_time,approx_nrg_reward,from_addr,to_addr,approx_value,transaction_nrg_consumed,nrg_price FROM aion.block_tx_warehouse WHERE toDate(block_timestamp) >= toDate('2018-05-14 00:00:00') AND 
               toDate(block_timestamp) <= toDate('2018-05-15 00:00:00') ORDER BY block_timestamp
2019-01-20 09:46:19,146 - [logs/pythonClickhouse.log:103]=> DATA SUCCESSFULLY LOADED FROM CLICKHOUSE:0
2019-01-20 09:46:24,171 - [logs/pythonClickhouse.log:80]=> load data start_date:2018-05-15 00:00:00
2019-01-20 09:46:24,171 - [logs/pythonClickhouse.log:81]=> load_data  to_date:2018-05-16 00:00:00
2019-01-20 09:46:24,172 - [logs/pythonClickhouse.log:74]=> query:SELECT block_timestamp,difficulty,block_nrg_consumed,nrg_limit,num_transactions,block_size,block_time,approx_nrg_reward,from_addr,to_addr,approx_value,transaction_nrg_consumed,nrg_price FROM aion.block_tx_warehouse WHERE toDate(block_timestamp) >= toDate('2018-05-15 00:00:00') AND 
               toDate(block_timestamp) <= toDate('2018-05-16 00:00:00') ORDER BY block_timestamp
2019-01-20 09:46:24,295 - [logs/pythonClickhouse.log:103]=> DATA SUCCESSFULLY LOADED FROM CLICKHOUSE:0
2019-01-20 09:46:29,322 - [logs/pythonClickhouse.log:80]=> load data start_date:2018-05-16 00:00:00
2019-01-20 09:46:29,322 - [logs/pythonClickhouse.log:81]=> load_data  to_date:2018-05-17 00:00:00
2019-01-20 09:46:29,323 - [logs/pythonClickhouse.log:74]=> query:SELECT block_timestamp,difficulty,block_nrg_consumed,nrg_limit,num_transactions,block_size,block_time,approx_nrg_reward,from_addr,to_addr,approx_value,transaction_nrg_consumed,nrg_price FROM aion.block_tx_warehouse WHERE toDate(block_timestamp) >= toDate('2018-05-16 00:00:00') AND 
               toDate(block_timestamp) <= toDate('2018-05-17 00:00:00') ORDER BY block_timestamp
2019-01-20 09:46:29,446 - [logs/pythonClickhouse.log:103]=> DATA SUCCESSFULLY LOADED FROM CLICKHOUSE:0
2019-01-20 09:46:34,472 - [logs/pythonClickhouse.log:80]=> load data start_date:2018-05-17 00:00:00
2019-01-20 09:46:34,473 - [logs/pythonClickhouse.log:81]=> load_data  to_date:2018-05-18 00:00:00
2019-01-20 09:46:34,473 - [logs/pythonClickhouse.log:74]=> query:SELECT block_timestamp,difficulty,block_nrg_consumed,nrg_limit,num_transactions,block_size,block_time,approx_nrg_reward,from_addr,to_addr,approx_value,transaction_nrg_consumed,nrg_price FROM aion.block_tx_warehouse WHERE toDate(block_timestamp) >= toDate('2018-05-17 00:00:00') AND 
               toDate(block_timestamp) <= toDate('2018-05-18 00:00:00') ORDER BY block_timestamp
2019-01-20 09:46:34,608 - [logs/pythonClickhouse.log:103]=> DATA SUCCESSFULLY LOADED FROM CLICKHOUSE:0
2019-01-20 09:46:39,632 - [logs/pythonClickhouse.log:80]=> load data start_date:2018-05-18 00:00:00
2019-01-20 09:46:39,633 - [logs/pythonClickhouse.log:81]=> load_data  to_date:2018-05-19 00:00:00
2019-01-20 09:46:39,633 - [logs/pythonClickhouse.log:74]=> query:SELECT block_timestamp,difficulty,block_nrg_consumed,nrg_limit,num_transactions,block_size,block_time,approx_nrg_reward,from_addr,to_addr,approx_value,transaction_nrg_consumed,nrg_price FROM aion.block_tx_warehouse WHERE toDate(block_timestamp) >= toDate('2018-05-18 00:00:00') AND 
               toDate(block_timestamp) <= toDate('2018-05-19 00:00:00') ORDER BY block_timestamp
2019-01-20 09:46:39,753 - [logs/pythonClickhouse.log:103]=> DATA SUCCESSFULLY LOADED FROM CLICKHOUSE:0
2019-01-20 09:46:44,777 - [logs/pythonClickhouse.log:80]=> load data start_date:2018-05-19 00:00:00
2019-01-20 09:46:44,777 - [logs/pythonClickhouse.log:81]=> load_data  to_date:2018-05-20 00:00:00
2019-01-20 09:46:44,778 - [logs/pythonClickhouse.log:74]=> query:SELECT block_timestamp,difficulty,block_nrg_consumed,nrg_limit,num_transactions,block_size,block_time,approx_nrg_reward,from_addr,to_addr,approx_value,transaction_nrg_consumed,nrg_price FROM aion.block_tx_warehouse WHERE toDate(block_timestamp) >= toDate('2018-05-19 00:00:00') AND 
               toDate(block_timestamp) <= toDate('2018-05-20 00:00:00') ORDER BY block_timestamp
2019-01-20 09:46:44,897 - [logs/pythonClickhouse.log:103]=> DATA SUCCESSFULLY LOADED FROM CLICKHOUSE:0
2019-01-20 09:46:49,926 - [logs/pythonClickhouse.log:80]=> load data start_date:2018-05-20 00:00:00
2019-01-20 09:46:49,926 - [logs/pythonClickhouse.log:81]=> load_data  to_date:2018-05-21 00:00:00
2019-01-20 09:46:49,927 - [logs/pythonClickhouse.log:74]=> query:SELECT block_timestamp,difficulty,block_nrg_consumed,nrg_limit,num_transactions,block_size,block_time,approx_nrg_reward,from_addr,to_addr,approx_value,transaction_nrg_consumed,nrg_price FROM aion.block_tx_warehouse WHERE toDate(block_timestamp) >= toDate('2018-05-20 00:00:00') AND 
               toDate(block_timestamp) <= toDate('2018-05-21 00:00:00') ORDER BY block_timestamp
2019-01-20 09:46:50,177 - [logs/pythonClickhouse.log:103]=> DATA SUCCESSFULLY LOADED FROM CLICKHOUSE:9976
2019-01-28 15:54:22,732 - [logs/pythonClickhouse.log:17]=> logs/pythonClickhouse.log
2019-01-28 15:54:28,872 - [logs/pythonClickhouse.log:103]=> DATA SUCCESSFULLY LOADED FROM CLICKHOUSE:208699
2019-01-28 15:54:34,927 - [logs/pythonClickhouse.log:103]=> DATA SUCCESSFULLY LOADED FROM CLICKHOUSE:211752
2019-01-28 15:54:36,102 - [logs/pythonClickhouse.log:251]=> insert_df
Traceback (most recent call last):
  File "/home/andre/anaconda3/envs/analytics/lib/python3.5/site-packages/pandahouse/http.py", line 45, in execute
    response.raise_for_status()
  File "/home/andre/anaconda3/envs/analytics/lib/python3.5/site-packages/requests/models.py", line 939, in raise_for_status
    raise HTTPError(http_error_msg, response=self)
requests.exceptions.HTTPError: 500 Server Error: Internal Server Error for url: http://127.0.0.1:8123/?query=INSERT+INTO+%60aion%60.%60network_activity%60+%28%60block_timestamp%60%2C+%60from_addr_new%60%2C+%60from_addr_churned%60%2C+%60from_addr_retained%60%2C+%60from_addr_active%60%2C+%60from_addr_new_lst%60%2C+%60from_addr_churned_lst%60%2C+%60from_addr_retained_lst%60%2C+%60from_addr_active_lst%60%2C+%60to_addr_new_lst%60%2C+%60to_addr_churned_lst%60%2C+%60to_addr_retained_lst%60%2C+%60to_addr_active_lst%60%2C+%60to_addr_new%60%2C+%60to_addr_churned%60%2C+%60to_addr_retained%60%2C+%60to_addr_active%60%2C+%60block_size%60%2C+%60block_time%60%2C+%60difficulty%60%2C+%60nrg_limit%60%2C+%60approx_nrg_reward%60%2C+%60num_transactions%60%2C+%60block_nrg_consumed%60%2C+%60nrg_price%60%2C+%60approx_value%60%2C+%60transaction_nrg_consumed%60%2C+%60block_year%60%2C+%60block_month%60%2C+%60block_day%60%2C+%60day_of_week%60%29+FORMAT+CSV

During handling of the above exception, another exception occurred:

Traceback (most recent call last):
  File "/home/andre/aion/data_science/bokeh/mysql_clickhouse_streamer/scripts/storage/pythonClickhouse.py", line 248, in insert_df
    affected_rows = pandahouse.to_clickhouse(df, table=table, connection=self.conn, index=False)
  File "/home/andre/anaconda3/envs/analytics/lib/python3.5/site-packages/pandahouse/core.py", line 64, in to_clickhouse
    execute(query, data=to_csv(chunk), connection=connection)
  File "/home/andre/anaconda3/envs/analytics/lib/python3.5/site-packages/pandahouse/http.py", line 48, in execute
    raise ClickhouseException(response.content)
pandahouse.http.ClickhouseException: b'Code: 27, e.displayText() = DB::Exception: Cannot parse input: expected " before: a00e54056a9b348c2bf9107eb71b4e10e87f33388f0618aaf2663f551dfa8797,a006ab3aa29eb1d0c8db4ad20a783a55e8e35b22ced39a49e3b975ec98ec967c,a02fcb8800a9663b9b1c3c4e380638: (at row 1)\n\nRow 1:\nColumn 0,   name: block_timestamp,          type: Date,    parsed text: "<DOUBLE QUOTE>2018-05-02<DOUBLE QUOTE>"\nColumn 1,   name: from_addr_new,            type: UInt64,  ERROR: text "<DOUBLE QUOTE>a00e54056" is not like UInt64\n\n, e.what() = DB::Exception\n'
2019-01-28 15:54:42,825 - [logs/pythonClickhouse.log:103]=> DATA SUCCESSFULLY LOADED FROM CLICKHOUSE:201886
2019-01-28 15:54:48,388 - [logs/pythonClickhouse.log:103]=> DATA SUCCESSFULLY LOADED FROM CLICKHOUSE:202069
2019-01-28 15:54:49,477 - [logs/pythonClickhouse.log:251]=> insert_df
Traceback (most recent call last):
  File "/home/andre/anaconda3/envs/analytics/lib/python3.5/site-packages/pandahouse/http.py", line 45, in execute
    response.raise_for_status()
  File "/home/andre/anaconda3/envs/analytics/lib/python3.5/site-packages/requests/models.py", line 939, in raise_for_status
    raise HTTPError(http_error_msg, response=self)
requests.exceptions.HTTPError: 500 Server Error: Internal Server Error for url: http://127.0.0.1:8123/?query=INSERT+INTO+%60aion%60.%60network_activity%60+%28%60block_timestamp%60%2C+%60from_addr_new%60%2C+%60from_addr_churned%60%2C+%60from_addr_retained%60%2C+%60from_addr_active%60%2C+%60from_addr_new_lst%60%2C+%60from_addr_churned_lst%60%2C+%60from_addr_retained_lst%60%2C+%60from_addr_active_lst%60%2C+%60to_addr_new_lst%60%2C+%60to_addr_churned_lst%60%2C+%60to_addr_retained_lst%60%2C+%60to_addr_active_lst%60%2C+%60to_addr_new%60%2C+%60to_addr_churned%60%2C+%60to_addr_retained%60%2C+%60to_addr_active%60%2C+%60block_size%60%2C+%60block_time%60%2C+%60difficulty%60%2C+%60nrg_limit%60%2C+%60approx_nrg_reward%60%2C+%60num_transactions%60%2C+%60block_nrg_consumed%60%2C+%60nrg_price%60%2C+%60approx_value%60%2C+%60transaction_nrg_consumed%60%2C+%60block_year%60%2C+%60block_month%60%2C+%60block_day%60%2C+%60day_of_week%60%29+FORMAT+CSV

During handling of the above exception, another exception occurred:

Traceback (most recent call last):
  File "/home/andre/aion/data_science/bokeh/mysql_clickhouse_streamer/scripts/storage/pythonClickhouse.py", line 248, in insert_df
    affected_rows = pandahouse.to_clickhouse(df, table=table, connection=self.conn, index=False)
  File "/home/andre/anaconda3/envs/analytics/lib/python3.5/site-packages/pandahouse/core.py", line 64, in to_clickhouse
    execute(query, data=to_csv(chunk), connection=connection)
  File "/home/andre/anaconda3/envs/analytics/lib/python3.5/site-packages/pandahouse/http.py", line 48, in execute
    raise ClickhouseException(response.content)
pandahouse.http.ClickhouseException: b'Code: 27, e.displayText() = DB::Exception: Cannot parse input: expected " before: a091792ff6ddc717e7a8c440dd3f1d471c5c02aa8f89aa204d711e097cbd79de,a044d1af4f4e65c4bcbf298b6d93dd2842ab16035cd13094af061034d0b01ef4,a006ab3aa29eb1d0c8db4ad20a783a: (at row 1)\n\nRow 1:\nColumn 0,   name: block_timestamp,          type: Date,    parsed text: "<DOUBLE QUOTE>2018-05-04<DOUBLE QUOTE>"\nColumn 1,   name: from_addr_new,            type: UInt64,  ERROR: text "<DOUBLE QUOTE>a091792ff" is not like UInt64\n\n, e.what() = DB::Exception\n'
2019-01-28 15:54:53,641 - [logs/pythonClickhouse.log:103]=> DATA SUCCESSFULLY LOADED FROM CLICKHOUSE:201936
2019-01-28 15:54:58,789 - [logs/pythonClickhouse.log:103]=> DATA SUCCESSFULLY LOADED FROM CLICKHOUSE:192787
2019-01-28 15:54:59,888 - [logs/pythonClickhouse.log:251]=> insert_df
Traceback (most recent call last):
  File "/home/andre/anaconda3/envs/analytics/lib/python3.5/site-packages/pandahouse/http.py", line 45, in execute
    response.raise_for_status()
  File "/home/andre/anaconda3/envs/analytics/lib/python3.5/site-packages/requests/models.py", line 939, in raise_for_status
    raise HTTPError(http_error_msg, response=self)
requests.exceptions.HTTPError: 500 Server Error: Internal Server Error for url: http://127.0.0.1:8123/?query=INSERT+INTO+%60aion%60.%60network_activity%60+%28%60block_timestamp%60%2C+%60from_addr_new%60%2C+%60from_addr_churned%60%2C+%60from_addr_retained%60%2C+%60from_addr_active%60%2C+%60from_addr_new_lst%60%2C+%60from_addr_churned_lst%60%2C+%60from_addr_retained_lst%60%2C+%60from_addr_active_lst%60%2C+%60to_addr_new_lst%60%2C+%60to_addr_churned_lst%60%2C+%60to_addr_retained_lst%60%2C+%60to_addr_active_lst%60%2C+%60to_addr_new%60%2C+%60to_addr_churned%60%2C+%60to_addr_retained%60%2C+%60to_addr_active%60%2C+%60block_size%60%2C+%60block_time%60%2C+%60difficulty%60%2C+%60nrg_limit%60%2C+%60approx_nrg_reward%60%2C+%60num_transactions%60%2C+%60block_nrg_consumed%60%2C+%60nrg_price%60%2C+%60approx_value%60%2C+%60transaction_nrg_consumed%60%2C+%60block_year%60%2C+%60block_month%60%2C+%60block_day%60%2C+%60day_of_week%60%29+FORMAT+CSV

During handling of the above exception, another exception occurred:

Traceback (most recent call last):
  File "/home/andre/aion/data_science/bokeh/mysql_clickhouse_streamer/scripts/storage/pythonClickhouse.py", line 248, in insert_df
    affected_rows = pandahouse.to_clickhouse(df, table=table, connection=self.conn, index=False)
  File "/home/andre/anaconda3/envs/analytics/lib/python3.5/site-packages/pandahouse/core.py", line 64, in to_clickhouse
    execute(query, data=to_csv(chunk), connection=connection)
  File "/home/andre/anaconda3/envs/analytics/lib/python3.5/site-packages/pandahouse/http.py", line 48, in execute
    raise ClickhouseException(response.content)
pandahouse.http.ClickhouseException: b'Code: 27, e.displayText() = DB::Exception: Cannot parse input: expected " before: a091792ff6ddc717e7a8c440dd3f1d471c5c02aa8f89aa204d711e097cbd79de,a032216688c6109770eb8a0483f87b42b782414bd02b77601cd045776964a6ec,a044d1af4f4e65c4bcbf298b6d93dd: (at row 1)\n\nRow 1:\nColumn 0,   name: block_timestamp,          type: Date,    parsed text: "<DOUBLE QUOTE>2018-05-06<DOUBLE QUOTE>"\nColumn 1,   name: from_addr_new,            type: UInt64,  ERROR: text "<DOUBLE QUOTE>a091792ff" is not like UInt64\n\n, e.what() = DB::Exception\n'
2019-01-28 15:55:18,305 - [logs/pythonClickhouse.log:17]=> logs/pythonClickhouse.log
2019-01-28 15:55:23,167 - [logs/pythonClickhouse.log:103]=> DATA SUCCESSFULLY LOADED FROM CLICKHOUSE:208699
2019-01-28 15:57:21,943 - [logs/pythonClickhouse.log:17]=> logs/pythonClickhouse.log
2019-01-28 15:57:26,262 - [logs/pythonClickhouse.log:103]=> DATA SUCCESSFULLY LOADED FROM CLICKHOUSE:208699
2019-01-28 15:59:30,096 - [logs/pythonClickhouse.log:17]=> logs/pythonClickhouse.log
2019-01-28 15:59:32,667 - [logs/pythonClickhouse.log:103]=> DATA SUCCESSFULLY LOADED FROM CLICKHOUSE:208699
2019-01-28 15:59:38,624 - [logs/pythonClickhouse.log:103]=> DATA SUCCESSFULLY LOADED FROM CLICKHOUSE:211752
2019-01-28 15:59:40,174 - [logs/pythonClickhouse.log:251]=> insert_df
Traceback (most recent call last):
  File "/home/andre/anaconda3/envs/analytics/lib/python3.5/site-packages/pandahouse/http.py", line 45, in execute
    response.raise_for_status()
  File "/home/andre/anaconda3/envs/analytics/lib/python3.5/site-packages/requests/models.py", line 939, in raise_for_status
    raise HTTPError(http_error_msg, response=self)
requests.exceptions.HTTPError: 500 Server Error: Internal Server Error for url: http://127.0.0.1:8123/?query=INSERT+INTO+%60aion%60.%60network_activity%60+%28%60block_timestamp%60%2C+%60from_addr_new%60%2C+%60from_addr_churned%60%2C+%60from_addr_retained%60%2C+%60from_addr_active%60%2C+%60from_addr_new_lst%60%2C+%60from_addr_churned_lst%60%2C+%60from_addr_retained_lst%60%2C+%60from_addr_active_lst%60%2C+%60to_addr_new_lst%60%2C+%60to_addr_churned_lst%60%2C+%60to_addr_retained_lst%60%2C+%60to_addr_active_lst%60%2C+%60to_addr_new%60%2C+%60to_addr_churned%60%2C+%60to_addr_retained%60%2C+%60to_addr_active%60%2C+%60block_size%60%2C+%60block_time%60%2C+%60difficulty%60%2C+%60nrg_limit%60%2C+%60approx_nrg_reward%60%2C+%60num_transactions%60%2C+%60block_nrg_consumed%60%2C+%60nrg_price%60%2C+%60approx_value%60%2C+%60transaction_nrg_consumed%60%2C+%60block_year%60%2C+%60block_month%60%2C+%60block_day%60%2C+%60day_of_week%60%29+FORMAT+CSV

During handling of the above exception, another exception occurred:

Traceback (most recent call last):
  File "/home/andre/aion/data_science/bokeh/mysql_clickhouse_streamer/scripts/storage/pythonClickhouse.py", line 248, in insert_df
    affected_rows = pandahouse.to_clickhouse(df, table=table, connection=self.conn, index=False)
  File "/home/andre/anaconda3/envs/analytics/lib/python3.5/site-packages/pandahouse/core.py", line 64, in to_clickhouse
    execute(query, data=to_csv(chunk), connection=connection)
  File "/home/andre/anaconda3/envs/analytics/lib/python3.5/site-packages/pandahouse/http.py", line 48, in execute
    raise ClickhouseException(response.content)
pandahouse.http.ClickhouseException: b'Code: 27, e.displayText() = DB::Exception: Cannot parse input: expected " before: a010783eb3775017aac976f68f1e893fd4c372aa0cf016eedce798d828de3fbd,a05bcaf3b86728600e31ee50d7654f2b115bf0b15a6d25c8200bb66fdf062fbb,a075271269a634b22f566b0fcc0269: (at row 1)\n\nRow 1:\nColumn 0,   name: block_timestamp,          type: Date,    parsed text: "<DOUBLE QUOTE>2018-05-02<DOUBLE QUOTE>"\nColumn 1,   name: from_addr_new,            type: UInt64,  ERROR: text "<DOUBLE QUOTE>a010783eb" is not like UInt64\n\n, e.what() = DB::Exception\n'
2019-01-28 16:01:59,362 - [logs/pythonClickhouse.log:17]=> logs/pythonClickhouse.log
2019-01-28 16:02:02,254 - [logs/pythonClickhouse.log:103]=> DATA SUCCESSFULLY LOADED FROM CLICKHOUSE:208699
2019-01-28 16:02:07,151 - [logs/pythonClickhouse.log:103]=> DATA SUCCESSFULLY LOADED FROM CLICKHOUSE:211752
2019-01-28 16:02:08,422 - [logs/pythonClickhouse.log:251]=> insert_df
Traceback (most recent call last):
  File "/home/andre/anaconda3/envs/analytics/lib/python3.5/site-packages/pandahouse/http.py", line 45, in execute
    response.raise_for_status()
  File "/home/andre/anaconda3/envs/analytics/lib/python3.5/site-packages/requests/models.py", line 939, in raise_for_status
    raise HTTPError(http_error_msg, response=self)
requests.exceptions.HTTPError: 500 Server Error: Internal Server Error for url: http://127.0.0.1:8123/?query=INSERT+INTO+%60aion%60.%60network_activity%60+%28%60block_timestamp%60%2C+%60from_addr_new%60%2C+%60from_addr_churned%60%2C+%60from_addr_retained%60%2C+%60from_addr_active%60%2C+%60from_addr_new_lst%60%2C+%60from_addr_churned_lst%60%2C+%60from_addr_retained_lst%60%2C+%60from_addr_active_lst%60%2C+%60to_addr_new_lst%60%2C+%60to_addr_churned_lst%60%2C+%60to_addr_retained_lst%60%2C+%60to_addr_active_lst%60%2C+%60to_addr_new%60%2C+%60to_addr_churned%60%2C+%60to_addr_retained%60%2C+%60to_addr_active%60%2C+%60block_size%60%2C+%60block_time%60%2C+%60difficulty%60%2C+%60nrg_limit%60%2C+%60approx_nrg_reward%60%2C+%60num_transactions%60%2C+%60block_nrg_consumed%60%2C+%60nrg_price%60%2C+%60approx_value%60%2C+%60transaction_nrg_consumed%60%2C+%60block_year%60%2C+%60block_month%60%2C+%60block_day%60%2C+%60day_of_week%60%29+FORMAT+CSV

During handling of the above exception, another exception occurred:

Traceback (most recent call last):
  File "/home/andre/aion/data_science/bokeh/mysql_clickhouse_streamer/scripts/storage/pythonClickhouse.py", line 248, in insert_df
    affected_rows = pandahouse.to_clickhouse(df, table=table, connection=self.conn, index=False)
  File "/home/andre/anaconda3/envs/analytics/lib/python3.5/site-packages/pandahouse/core.py", line 64, in to_clickhouse
    execute(query, data=to_csv(chunk), connection=connection)
  File "/home/andre/anaconda3/envs/analytics/lib/python3.5/site-packages/pandahouse/http.py", line 48, in execute
    raise ClickhouseException(response.content)
pandahouse.http.ClickhouseException: b'Code: 27, e.displayText() = DB::Exception: Cannot parse input: expected " before: a07f698e358a96d2c5e188971d57919965333fde138dcd58410d63ba586c9e20,a08195c2329bf3d6fac075c1c9555ec4baddaae00a534364089944b2a15bf955,a00f5d2b5293a493d5d023630952eb: (at row 1)\n\nRow 1:\nColumn 0,   name: block_timestamp,          type: Date,    parsed text: "<DOUBLE QUOTE>2018-05-02<DOUBLE QUOTE>"\nColumn 1,   name: from_addr_new,            type: UInt64,  ERROR: text "<DOUBLE QUOTE>a07f698e3" is not like UInt64\n\n, e.what() = DB::Exception\n'
2019-01-28 16:02:12,019 - [logs/pythonClickhouse.log:103]=> DATA SUCCESSFULLY LOADED FROM CLICKHOUSE:201886
2019-01-28 16:03:19,649 - [logs/pythonClickhouse.log:17]=> logs/pythonClickhouse.log
2019-01-28 16:03:24,139 - [logs/pythonClickhouse.log:103]=> DATA SUCCESSFULLY LOADED FROM CLICKHOUSE:208699
2019-01-28 16:03:28,939 - [logs/pythonClickhouse.log:103]=> DATA SUCCESSFULLY LOADED FROM CLICKHOUSE:211752
2019-01-28 16:03:30,156 - [logs/pythonClickhouse.log:251]=> insert_df
Traceback (most recent call last):
  File "/home/andre/anaconda3/envs/analytics/lib/python3.5/site-packages/pandahouse/http.py", line 45, in execute
    response.raise_for_status()
  File "/home/andre/anaconda3/envs/analytics/lib/python3.5/site-packages/requests/models.py", line 939, in raise_for_status
    raise HTTPError(http_error_msg, response=self)
requests.exceptions.HTTPError: 500 Server Error: Internal Server Error for url: http://127.0.0.1:8123/?query=INSERT+INTO+%60aion%60.%60network_activity%60+%28%60block_timestamp%60%2C+%60from_addr_new%60%2C+%60from_addr_churned%60%2C+%60from_addr_retained%60%2C+%60from_addr_active%60%2C+%60from_addr_new_lst%60%2C+%60from_addr_churned_lst%60%2C+%60from_addr_retained_lst%60%2C+%60from_addr_active_lst%60%2C+%60to_addr_new_lst%60%2C+%60to_addr_churned_lst%60%2C+%60to_addr_retained_lst%60%2C+%60to_addr_active_lst%60%2C+%60to_addr_new%60%2C+%60to_addr_churned%60%2C+%60to_addr_retained%60%2C+%60to_addr_active%60%2C+%60block_size%60%2C+%60block_time%60%2C+%60difficulty%60%2C+%60nrg_limit%60%2C+%60approx_nrg_reward%60%2C+%60num_transactions%60%2C+%60block_nrg_consumed%60%2C+%60nrg_price%60%2C+%60approx_value%60%2C+%60transaction_nrg_consumed%60%2C+%60block_year%60%2C+%60block_month%60%2C+%60block_day%60%2C+%60day_of_week%60%29+FORMAT+CSV

During handling of the above exception, another exception occurred:

Traceback (most recent call last):
  File "/home/andre/aion/data_science/bokeh/mysql_clickhouse_streamer/scripts/storage/pythonClickhouse.py", line 248, in insert_df
    affected_rows = pandahouse.to_clickhouse(df, table=table, connection=self.conn, index=False)
  File "/home/andre/anaconda3/envs/analytics/lib/python3.5/site-packages/pandahouse/core.py", line 64, in to_clickhouse
    execute(query, data=to_csv(chunk), connection=connection)
  File "/home/andre/anaconda3/envs/analytics/lib/python3.5/site-packages/pandahouse/http.py", line 48, in execute
    raise ClickhouseException(response.content)
pandahouse.http.ClickhouseException: b'Code: 27, e.displayText() = DB::Exception: Cannot parse input: expected " before: a032216688c6109770eb8a0483f87b42b782414bd02b77601cd045776964a6ec,a0fb44c6007b9d0ccbf7ff7b0a33c38712fd480b9c6b8d48c3f368ae12b8f7b5,a006ab3aa29eb1d0c8db4ad20a783a: (at row 1)\n\nRow 1:\nColumn 0,   name: block_timestamp,          type: Date,    parsed text: "<DOUBLE QUOTE>2018-05-02<DOUBLE QUOTE>"\nColumn 1,   name: from_addr_new,            type: UInt64,  ERROR: text "<DOUBLE QUOTE>a03221668" is not like UInt64\n\n, e.what() = DB::Exception\n'
2019-01-28 16:03:35,484 - [logs/pythonClickhouse.log:103]=> DATA SUCCESSFULLY LOADED FROM CLICKHOUSE:201886
2019-01-28 16:05:00,571 - [logs/pythonClickhouse.log:17]=> logs/pythonClickhouse.log
2019-01-28 16:05:06,335 - [logs/pythonClickhouse.log:103]=> DATA SUCCESSFULLY LOADED FROM CLICKHOUSE:208699
2019-01-28 16:05:12,163 - [logs/pythonClickhouse.log:103]=> DATA SUCCESSFULLY LOADED FROM CLICKHOUSE:211752
2019-01-28 16:05:13,451 - [logs/pythonClickhouse.log:251]=> insert_df
Traceback (most recent call last):
  File "/home/andre/anaconda3/envs/analytics/lib/python3.5/site-packages/pandahouse/http.py", line 45, in execute
    response.raise_for_status()
  File "/home/andre/anaconda3/envs/analytics/lib/python3.5/site-packages/requests/models.py", line 939, in raise_for_status
    raise HTTPError(http_error_msg, response=self)
requests.exceptions.HTTPError: 500 Server Error: Internal Server Error for url: http://127.0.0.1:8123/?query=INSERT+INTO+%60aion%60.%60network_activity%60+%28%60block_timestamp%60%2C+%60from_addr_new%60%2C+%60from_addr_churned%60%2C+%60from_addr_retained%60%2C+%60from_addr_active%60%2C+%60from_addr_new_lst%60%2C+%60from_addr_churned_lst%60%2C+%60from_addr_retained_lst%60%2C+%60from_addr_active_lst%60%2C+%60to_addr_new_lst%60%2C+%60to_addr_churned_lst%60%2C+%60to_addr_retained_lst%60%2C+%60to_addr_active_lst%60%2C+%60to_addr_new%60%2C+%60to_addr_churned%60%2C+%60to_addr_retained%60%2C+%60to_addr_active%60%2C+%60block_size%60%2C+%60block_time%60%2C+%60difficulty%60%2C+%60nrg_limit%60%2C+%60approx_nrg_reward%60%2C+%60num_transactions%60%2C+%60block_nrg_consumed%60%2C+%60nrg_price%60%2C+%60approx_value%60%2C+%60transaction_nrg_consumed%60%2C+%60block_year%60%2C+%60block_month%60%2C+%60block_day%60%2C+%60day_of_week%60%29+FORMAT+CSV

During handling of the above exception, another exception occurred:

Traceback (most recent call last):
  File "/home/andre/aion/data_science/bokeh/mysql_clickhouse_streamer/scripts/storage/pythonClickhouse.py", line 248, in insert_df
    affected_rows = pandahouse.to_clickhouse(df, table=table, connection=self.conn, index=False)
  File "/home/andre/anaconda3/envs/analytics/lib/python3.5/site-packages/pandahouse/core.py", line 64, in to_clickhouse
    execute(query, data=to_csv(chunk), connection=connection)
  File "/home/andre/anaconda3/envs/analytics/lib/python3.5/site-packages/pandahouse/http.py", line 48, in execute
    raise ClickhouseException(response.content)
pandahouse.http.ClickhouseException: b'Code: 27, e.displayText() = DB::Exception: Cannot parse input: expected " before: a010783eb3775017aac976f68f1e893fd4c372aa0cf016eedce798d828de3fbd,a080349a3349a0c4a0a90e58b48510a4f9ad5d9adf9a0324fc5773ab9323bb14,a06dc1f0daa40ea95f80fbe9def2fc: (at row 1)\n\nRow 1:\nColumn 0,   name: block_timestamp,          type: Date,    parsed text: "<DOUBLE QUOTE>2018-05-02<DOUBLE QUOTE>"\nColumn 1,   name: from_addr_new,            type: UInt64,  ERROR: text "<DOUBLE QUOTE>a010783eb" is not like UInt64\n\n, e.what() = DB::Exception\n'
2019-01-28 16:16:52,379 - [logs/pythonClickhouse.log:17]=> logs/pythonClickhouse.log
2019-01-28 16:17:13,166 - [logs/pythonClickhouse.log:17]=> logs/pythonClickhouse.log
2019-01-28 16:17:17,555 - [logs/pythonClickhouse.log:103]=> DATA SUCCESSFULLY LOADED FROM CLICKHOUSE:208699
2019-01-28 16:17:22,550 - [logs/pythonClickhouse.log:103]=> DATA SUCCESSFULLY LOADED FROM CLICKHOUSE:211752
2019-01-28 16:17:23,768 - [logs/pythonClickhouse.log:251]=> insert_df
Traceback (most recent call last):
  File "/home/andre/anaconda3/envs/analytics/lib/python3.5/site-packages/pandahouse/http.py", line 45, in execute
    response.raise_for_status()
  File "/home/andre/anaconda3/envs/analytics/lib/python3.5/site-packages/requests/models.py", line 939, in raise_for_status
    raise HTTPError(http_error_msg, response=self)
requests.exceptions.HTTPError: 500 Server Error: Internal Server Error for url: http://127.0.0.1:8123/?query=INSERT+INTO+%60aion%60.%60network_activity%60+%28%60block_timestamp%60%2C+%60from_addr_new%60%2C+%60from_addr_churned%60%2C+%60from_addr_retained%60%2C+%60from_addr_active%60%2C+%60from_addr_new_lst%60%2C+%60from_addr_churned_lst%60%2C+%60from_addr_retained_lst%60%2C+%60from_addr_active_lst%60%2C+%60to_addr_new_lst%60%2C+%60to_addr_churned_lst%60%2C+%60to_addr_retained_lst%60%2C+%60to_addr_active_lst%60%2C+%60to_addr_new%60%2C+%60to_addr_churned%60%2C+%60to_addr_retained%60%2C+%60to_addr_active%60%2C+%60block_size%60%2C+%60block_time%60%2C+%60difficulty%60%2C+%60nrg_limit%60%2C+%60approx_nrg_reward%60%2C+%60num_transactions%60%2C+%60block_nrg_consumed%60%2C+%60nrg_price%60%2C+%60approx_value%60%2C+%60transaction_nrg_consumed%60%2C+%60block_year%60%2C+%60block_month%60%2C+%60block_day%60%2C+%60day_of_week%60%29+FORMAT+CSV

During handling of the above exception, another exception occurred:

Traceback (most recent call last):
  File "/home/andre/aion/data_science/bokeh/mysql_clickhouse_streamer/scripts/storage/pythonClickhouse.py", line 248, in insert_df
    affected_rows = pandahouse.to_clickhouse(df, table=table, connection=self.conn, index=False)
  File "/home/andre/anaconda3/envs/analytics/lib/python3.5/site-packages/pandahouse/core.py", line 64, in to_clickhouse
    execute(query, data=to_csv(chunk), connection=connection)
  File "/home/andre/anaconda3/envs/analytics/lib/python3.5/site-packages/pandahouse/http.py", line 48, in execute
    raise ClickhouseException(response.content)
pandahouse.http.ClickhouseException: b'Code: 27, e.displayText() = DB::Exception: Cannot parse input: expected " before: a067d14d13405d1b877ce1a1dd50ae13d90c256d0828f6213fd1045519c95f0b,a04e625e67f21973403b6cc458f79d19e098e05a5540a7054c8f27e2adcbc00e,a006ab3aa29eb1d0c8db4ad20a783a: (at row 1)\n\nRow 1:\nColumn 0,   name: block_timestamp,          type: Date,    parsed text: "<DOUBLE QUOTE>2018-05-02<DOUBLE QUOTE>"\nColumn 1,   name: from_addr_new,            type: UInt64,  ERROR: text "<DOUBLE QUOTE>a067d14d1" is not like UInt64\n\n, e.what() = DB::Exception\n'
2019-01-28 16:17:27,291 - [logs/pythonClickhouse.log:103]=> DATA SUCCESSFULLY LOADED FROM CLICKHOUSE:201886
2019-01-28 16:17:32,368 - [logs/pythonClickhouse.log:103]=> DATA SUCCESSFULLY LOADED FROM CLICKHOUSE:202069
2019-01-28 16:17:34,109 - [logs/pythonClickhouse.log:251]=> insert_df
Traceback (most recent call last):
  File "/home/andre/anaconda3/envs/analytics/lib/python3.5/site-packages/pandahouse/http.py", line 45, in execute
    response.raise_for_status()
  File "/home/andre/anaconda3/envs/analytics/lib/python3.5/site-packages/requests/models.py", line 939, in raise_for_status
    raise HTTPError(http_error_msg, response=self)
requests.exceptions.HTTPError: 500 Server Error: Internal Server Error for url: http://127.0.0.1:8123/?query=INSERT+INTO+%60aion%60.%60network_activity%60+%28%60block_timestamp%60%2C+%60from_addr_new%60%2C+%60from_addr_churned%60%2C+%60from_addr_retained%60%2C+%60from_addr_active%60%2C+%60from_addr_new_lst%60%2C+%60from_addr_churned_lst%60%2C+%60from_addr_retained_lst%60%2C+%60from_addr_active_lst%60%2C+%60to_addr_new_lst%60%2C+%60to_addr_churned_lst%60%2C+%60to_addr_retained_lst%60%2C+%60to_addr_active_lst%60%2C+%60to_addr_new%60%2C+%60to_addr_churned%60%2C+%60to_addr_retained%60%2C+%60to_addr_active%60%2C+%60block_size%60%2C+%60block_time%60%2C+%60difficulty%60%2C+%60nrg_limit%60%2C+%60approx_nrg_reward%60%2C+%60num_transactions%60%2C+%60block_nrg_consumed%60%2C+%60nrg_price%60%2C+%60approx_value%60%2C+%60transaction_nrg_consumed%60%2C+%60block_year%60%2C+%60block_month%60%2C+%60block_day%60%2C+%60day_of_week%60%29+FORMAT+CSV

During handling of the above exception, another exception occurred:

Traceback (most recent call last):
  File "/home/andre/aion/data_science/bokeh/mysql_clickhouse_streamer/scripts/storage/pythonClickhouse.py", line 248, in insert_df
    affected_rows = pandahouse.to_clickhouse(df, table=table, connection=self.conn, index=False)
  File "/home/andre/anaconda3/envs/analytics/lib/python3.5/site-packages/pandahouse/core.py", line 64, in to_clickhouse
    execute(query, data=to_csv(chunk), connection=connection)
  File "/home/andre/anaconda3/envs/analytics/lib/python3.5/site-packages/pandahouse/http.py", line 48, in execute
    raise ClickhouseException(response.content)
pandahouse.http.ClickhouseException: b'Code: 27, e.displayText() = DB::Exception: Cannot parse input: expected " before: a067d14d13405d1b877ce1a1dd50ae13d90c256d0828f6213fd1045519c95f0b,a0219e582ed70748147d4274a34a5ab548a796ad2da3a9eed9441813be18dbee,a04e625e67f21973403b6cc458f79d: (at row 1)\n\nRow 1:\nColumn 0,   name: block_timestamp,          type: Date,    parsed text: "<DOUBLE QUOTE>2018-05-04<DOUBLE QUOTE>"\nColumn 1,   name: from_addr_new,            type: UInt64,  ERROR: text "<DOUBLE QUOTE>a067d14d1" is not like UInt64\n\n, e.what() = DB::Exception\n'
2019-01-28 16:17:39,380 - [logs/pythonClickhouse.log:103]=> DATA SUCCESSFULLY LOADED FROM CLICKHOUSE:201936
2019-01-28 16:17:43,954 - [logs/pythonClickhouse.log:103]=> DATA SUCCESSFULLY LOADED FROM CLICKHOUSE:192787
2019-01-28 16:17:45,062 - [logs/pythonClickhouse.log:251]=> insert_df
Traceback (most recent call last):
  File "/home/andre/anaconda3/envs/analytics/lib/python3.5/site-packages/pandahouse/http.py", line 45, in execute
    response.raise_for_status()
  File "/home/andre/anaconda3/envs/analytics/lib/python3.5/site-packages/requests/models.py", line 939, in raise_for_status
    raise HTTPError(http_error_msg, response=self)
requests.exceptions.HTTPError: 500 Server Error: Internal Server Error for url: http://127.0.0.1:8123/?query=INSERT+INTO+%60aion%60.%60network_activity%60+%28%60block_timestamp%60%2C+%60from_addr_new%60%2C+%60from_addr_churned%60%2C+%60from_addr_retained%60%2C+%60from_addr_active%60%2C+%60from_addr_new_lst%60%2C+%60from_addr_churned_lst%60%2C+%60from_addr_retained_lst%60%2C+%60from_addr_active_lst%60%2C+%60to_addr_new_lst%60%2C+%60to_addr_churned_lst%60%2C+%60to_addr_retained_lst%60%2C+%60to_addr_active_lst%60%2C+%60to_addr_new%60%2C+%60to_addr_churned%60%2C+%60to_addr_retained%60%2C+%60to_addr_active%60%2C+%60block_size%60%2C+%60block_time%60%2C+%60difficulty%60%2C+%60nrg_limit%60%2C+%60approx_nrg_reward%60%2C+%60num_transactions%60%2C+%60block_nrg_consumed%60%2C+%60nrg_price%60%2C+%60approx_value%60%2C+%60transaction_nrg_consumed%60%2C+%60block_year%60%2C+%60block_month%60%2C+%60block_day%60%2C+%60day_of_week%60%29+FORMAT+CSV

During handling of the above exception, another exception occurred:

Traceback (most recent call last):
  File "/home/andre/aion/data_science/bokeh/mysql_clickhouse_streamer/scripts/storage/pythonClickhouse.py", line 248, in insert_df
    affected_rows = pandahouse.to_clickhouse(df, table=table, connection=self.conn, index=False)
  File "/home/andre/anaconda3/envs/analytics/lib/python3.5/site-packages/pandahouse/core.py", line 64, in to_clickhouse
    execute(query, data=to_csv(chunk), connection=connection)
  File "/home/andre/anaconda3/envs/analytics/lib/python3.5/site-packages/pandahouse/http.py", line 48, in execute
    raise ClickhouseException(response.content)
pandahouse.http.ClickhouseException: b'Code: 27, e.displayText() = DB::Exception: Cannot parse input: expected " before: a067d14d13405d1b877ce1a1dd50ae13d90c256d0828f6213fd1045519c95f0b,a0219e582ed70748147d4274a34a5ab548a796ad2da3a9eed9441813be18dbee,a077be6a53ee1d11340b794570e6a9: (at row 1)\n\nRow 1:\nColumn 0,   name: block_timestamp,          type: Date,    parsed text: "<DOUBLE QUOTE>2018-05-06<DOUBLE QUOTE>"\nColumn 1,   name: from_addr_new,            type: UInt64,  ERROR: text "<DOUBLE QUOTE>a067d14d1" is not like UInt64\n\n, e.what() = DB::Exception\n'
2019-01-28 16:17:48,727 - [logs/pythonClickhouse.log:103]=> DATA SUCCESSFULLY LOADED FROM CLICKHOUSE:192399
2019-01-28 16:17:53,504 - [logs/pythonClickhouse.log:103]=> DATA SUCCESSFULLY LOADED FROM CLICKHOUSE:192499
2019-01-28 16:17:54,792 - [logs/pythonClickhouse.log:251]=> insert_df
Traceback (most recent call last):
  File "/home/andre/anaconda3/envs/analytics/lib/python3.5/site-packages/pandahouse/http.py", line 45, in execute
    response.raise_for_status()
  File "/home/andre/anaconda3/envs/analytics/lib/python3.5/site-packages/requests/models.py", line 939, in raise_for_status
    raise HTTPError(http_error_msg, response=self)
requests.exceptions.HTTPError: 500 Server Error: Internal Server Error for url: http://127.0.0.1:8123/?query=INSERT+INTO+%60aion%60.%60network_activity%60+%28%60block_timestamp%60%2C+%60from_addr_new%60%2C+%60from_addr_churned%60%2C+%60from_addr_retained%60%2C+%60from_addr_active%60%2C+%60from_addr_new_lst%60%2C+%60from_addr_churned_lst%60%2C+%60from_addr_retained_lst%60%2C+%60from_addr_active_lst%60%2C+%60to_addr_new_lst%60%2C+%60to_addr_churned_lst%60%2C+%60to_addr_retained_lst%60%2C+%60to_addr_active_lst%60%2C+%60to_addr_new%60%2C+%60to_addr_churned%60%2C+%60to_addr_retained%60%2C+%60to_addr_active%60%2C+%60block_size%60%2C+%60block_time%60%2C+%60difficulty%60%2C+%60nrg_limit%60%2C+%60approx_nrg_reward%60%2C+%60num_transactions%60%2C+%60block_nrg_consumed%60%2C+%60nrg_price%60%2C+%60approx_value%60%2C+%60transaction_nrg_consumed%60%2C+%60block_year%60%2C+%60block_month%60%2C+%60block_day%60%2C+%60day_of_week%60%29+FORMAT+CSV

During handling of the above exception, another exception occurred:

Traceback (most recent call last):
  File "/home/andre/aion/data_science/bokeh/mysql_clickhouse_streamer/scripts/storage/pythonClickhouse.py", line 248, in insert_df
    affected_rows = pandahouse.to_clickhouse(df, table=table, connection=self.conn, index=False)
  File "/home/andre/anaconda3/envs/analytics/lib/python3.5/site-packages/pandahouse/core.py", line 64, in to_clickhouse
    execute(query, data=to_csv(chunk), connection=connection)
  File "/home/andre/anaconda3/envs/analytics/lib/python3.5/site-packages/pandahouse/http.py", line 48, in execute
    raise ClickhouseException(response.content)
pandahouse.http.ClickhouseException: b'Code: 27, e.displayText() = DB::Exception: Cannot parse input: expected " before: a067d14d13405d1b877ce1a1dd50ae13d90c256d0828f6213fd1045519c95f0b,a0219e582ed70748147d4274a34a5ab548a796ad2da3a9eed9441813be18dbee,a077be6a53ee1d11340b794570e6a9: (at row 1)\n\nRow 1:\nColumn 0,   name: block_timestamp,          type: Date,    parsed text: "<DOUBLE QUOTE>2018-05-08<DOUBLE QUOTE>"\nColumn 1,   name: from_addr_new,            type: UInt64,  ERROR: text "<DOUBLE QUOTE>a067d14d1" is not like UInt64\n\n, e.what() = DB::Exception\n'
2019-01-28 16:17:57,988 - [logs/pythonClickhouse.log:103]=> DATA SUCCESSFULLY LOADED FROM CLICKHOUSE:183265
2019-01-28 16:18:02,599 - [logs/pythonClickhouse.log:103]=> DATA SUCCESSFULLY LOADED FROM CLICKHOUSE:183356
2019-01-28 16:18:03,872 - [logs/pythonClickhouse.log:251]=> insert_df
Traceback (most recent call last):
  File "/home/andre/anaconda3/envs/analytics/lib/python3.5/site-packages/pandahouse/http.py", line 45, in execute
    response.raise_for_status()
  File "/home/andre/anaconda3/envs/analytics/lib/python3.5/site-packages/requests/models.py", line 939, in raise_for_status
    raise HTTPError(http_error_msg, response=self)
requests.exceptions.HTTPError: 500 Server Error: Internal Server Error for url: http://127.0.0.1:8123/?query=INSERT+INTO+%60aion%60.%60network_activity%60+%28%60block_timestamp%60%2C+%60from_addr_new%60%2C+%60from_addr_churned%60%2C+%60from_addr_retained%60%2C+%60from_addr_active%60%2C+%60from_addr_new_lst%60%2C+%60from_addr_churned_lst%60%2C+%60from_addr_retained_lst%60%2C+%60from_addr_active_lst%60%2C+%60to_addr_new_lst%60%2C+%60to_addr_churned_lst%60%2C+%60to_addr_retained_lst%60%2C+%60to_addr_active_lst%60%2C+%60to_addr_new%60%2C+%60to_addr_churned%60%2C+%60to_addr_retained%60%2C+%60to_addr_active%60%2C+%60block_size%60%2C+%60block_time%60%2C+%60difficulty%60%2C+%60nrg_limit%60%2C+%60approx_nrg_reward%60%2C+%60num_transactions%60%2C+%60block_nrg_consumed%60%2C+%60nrg_price%60%2C+%60approx_value%60%2C+%60transaction_nrg_consumed%60%2C+%60block_year%60%2C+%60block_month%60%2C+%60block_day%60%2C+%60day_of_week%60%29+FORMAT+CSV

During handling of the above exception, another exception occurred:

Traceback (most recent call last):
  File "/home/andre/aion/data_science/bokeh/mysql_clickhouse_streamer/scripts/storage/pythonClickhouse.py", line 248, in insert_df
    affected_rows = pandahouse.to_clickhouse(df, table=table, connection=self.conn, index=False)
  File "/home/andre/anaconda3/envs/analytics/lib/python3.5/site-packages/pandahouse/core.py", line 64, in to_clickhouse
    execute(query, data=to_csv(chunk), connection=connection)
  File "/home/andre/anaconda3/envs/analytics/lib/python3.5/site-packages/pandahouse/http.py", line 48, in execute
    raise ClickhouseException(response.content)
pandahouse.http.ClickhouseException: b'Code: 27, e.displayText() = DB::Exception: Cannot parse input: expected " before: a067d14d13405d1b877ce1a1dd50ae13d90c256d0828f6213fd1045519c95f0b,a0219e582ed70748147d4274a34a5ab548a796ad2da3a9eed9441813be18dbee,a0c7e08b1baa0393c62152a65f99c7: (at row 1)\n\nRow 1:\nColumn 0,   name: block_timestamp,          type: Date,    parsed text: "<DOUBLE QUOTE>2018-05-10<DOUBLE QUOTE>"\nColumn 1,   name: from_addr_new,            type: UInt64,  ERROR: text "<DOUBLE QUOTE>a067d14d1" is not like UInt64\n\n, e.what() = DB::Exception\n'
2019-01-28 16:18:07,154 - [logs/pythonClickhouse.log:103]=> DATA SUCCESSFULLY LOADED FROM CLICKHOUSE:183760
2019-01-28 16:18:11,373 - [logs/pythonClickhouse.log:103]=> DATA SUCCESSFULLY LOADED FROM CLICKHOUSE:174848
2019-01-28 16:18:12,488 - [logs/pythonClickhouse.log:251]=> insert_df
Traceback (most recent call last):
  File "/home/andre/anaconda3/envs/analytics/lib/python3.5/site-packages/pandahouse/http.py", line 45, in execute
    response.raise_for_status()
  File "/home/andre/anaconda3/envs/analytics/lib/python3.5/site-packages/requests/models.py", line 939, in raise_for_status
    raise HTTPError(http_error_msg, response=self)
requests.exceptions.HTTPError: 500 Server Error: Internal Server Error for url: http://127.0.0.1:8123/?query=INSERT+INTO+%60aion%60.%60network_activity%60+%28%60block_timestamp%60%2C+%60from_addr_new%60%2C+%60from_addr_churned%60%2C+%60from_addr_retained%60%2C+%60from_addr_active%60%2C+%60from_addr_new_lst%60%2C+%60from_addr_churned_lst%60%2C+%60from_addr_retained_lst%60%2C+%60from_addr_active_lst%60%2C+%60to_addr_new_lst%60%2C+%60to_addr_churned_lst%60%2C+%60to_addr_retained_lst%60%2C+%60to_addr_active_lst%60%2C+%60to_addr_new%60%2C+%60to_addr_churned%60%2C+%60to_addr_retained%60%2C+%60to_addr_active%60%2C+%60block_size%60%2C+%60block_time%60%2C+%60difficulty%60%2C+%60nrg_limit%60%2C+%60approx_nrg_reward%60%2C+%60num_transactions%60%2C+%60block_nrg_consumed%60%2C+%60nrg_price%60%2C+%60approx_value%60%2C+%60transaction_nrg_consumed%60%2C+%60block_year%60%2C+%60block_month%60%2C+%60block_day%60%2C+%60day_of_week%60%29+FORMAT+CSV

During handling of the above exception, another exception occurred:

Traceback (most recent call last):
  File "/home/andre/aion/data_science/bokeh/mysql_clickhouse_streamer/scripts/storage/pythonClickhouse.py", line 248, in insert_df
    affected_rows = pandahouse.to_clickhouse(df, table=table, connection=self.conn, index=False)
  File "/home/andre/anaconda3/envs/analytics/lib/python3.5/site-packages/pandahouse/core.py", line 64, in to_clickhouse
    execute(query, data=to_csv(chunk), connection=connection)
  File "/home/andre/anaconda3/envs/analytics/lib/python3.5/site-packages/pandahouse/http.py", line 48, in execute
    raise ClickhouseException(response.content)
pandahouse.http.ClickhouseException: b'Code: 27, e.displayText() = DB::Exception: Cannot parse input: expected " before: a067d14d13405d1b877ce1a1dd50ae13d90c256d0828f6213fd1045519c95f0b,a075271269a634b22f566b0fcc026991d24afef8c7ee0d68a8f42f445b72657f,a0142ab225a1a561ed007610bba497: (at row 1)\n\nRow 1:\nColumn 0,   name: block_timestamp,          type: Date,    parsed text: "<DOUBLE QUOTE>2018-05-12<DOUBLE QUOTE>"\nColumn 1,   name: from_addr_new,            type: UInt64,  ERROR: text "<DOUBLE QUOTE>a067d14d1" is not like UInt64\n\n, e.what() = DB::Exception\n'
2019-01-28 16:18:15,620 - [logs/pythonClickhouse.log:103]=> DATA SUCCESSFULLY LOADED FROM CLICKHOUSE:175391
2019-01-28 16:18:20,325 - [logs/pythonClickhouse.log:103]=> DATA SUCCESSFULLY LOADED FROM CLICKHOUSE:175807
2019-01-28 16:18:21,666 - [logs/pythonClickhouse.log:251]=> insert_df
Traceback (most recent call last):
  File "/home/andre/anaconda3/envs/analytics/lib/python3.5/site-packages/pandahouse/http.py", line 45, in execute
    response.raise_for_status()
  File "/home/andre/anaconda3/envs/analytics/lib/python3.5/site-packages/requests/models.py", line 939, in raise_for_status
    raise HTTPError(http_error_msg, response=self)
requests.exceptions.HTTPError: 500 Server Error: Internal Server Error for url: http://127.0.0.1:8123/?query=INSERT+INTO+%60aion%60.%60network_activity%60+%28%60block_timestamp%60%2C+%60from_addr_new%60%2C+%60from_addr_churned%60%2C+%60from_addr_retained%60%2C+%60from_addr_active%60%2C+%60from_addr_new_lst%60%2C+%60from_addr_churned_lst%60%2C+%60from_addr_retained_lst%60%2C+%60from_addr_active_lst%60%2C+%60to_addr_new_lst%60%2C+%60to_addr_churned_lst%60%2C+%60to_addr_retained_lst%60%2C+%60to_addr_active_lst%60%2C+%60to_addr_new%60%2C+%60to_addr_churned%60%2C+%60to_addr_retained%60%2C+%60to_addr_active%60%2C+%60block_size%60%2C+%60block_time%60%2C+%60difficulty%60%2C+%60nrg_limit%60%2C+%60approx_nrg_reward%60%2C+%60num_transactions%60%2C+%60block_nrg_consumed%60%2C+%60nrg_price%60%2C+%60approx_value%60%2C+%60transaction_nrg_consumed%60%2C+%60block_year%60%2C+%60block_month%60%2C+%60block_day%60%2C+%60day_of_week%60%29+FORMAT+CSV

During handling of the above exception, another exception occurred:

Traceback (most recent call last):
  File "/home/andre/aion/data_science/bokeh/mysql_clickhouse_streamer/scripts/storage/pythonClickhouse.py", line 248, in insert_df
    affected_rows = pandahouse.to_clickhouse(df, table=table, connection=self.conn, index=False)
  File "/home/andre/anaconda3/envs/analytics/lib/python3.5/site-packages/pandahouse/core.py", line 64, in to_clickhouse
    execute(query, data=to_csv(chunk), connection=connection)
  File "/home/andre/anaconda3/envs/analytics/lib/python3.5/site-packages/pandahouse/http.py", line 48, in execute
    raise ClickhouseException(response.content)
pandahouse.http.ClickhouseException: b'Code: 27, e.displayText() = DB::Exception: Cannot parse input: expected " before: a0c7e08b1baa0393c62152a65f99c75319186ab354890660ab793fc170a6496c,a07568b330477453e489a37dc0ca5a29d09f10fd987d056096c790942c543360,a0ef10e5c17bddb4cfa77af683a646: (at row 1)\n\nRow 1:\nColumn 0,   name: block_timestamp,          type: Date,    parsed text: "<DOUBLE QUOTE>2018-05-14<DOUBLE QUOTE>"\nColumn 1,   name: from_addr_new,            type: UInt64,  ERROR: text "<DOUBLE QUOTE>a0c7e08b1" is not like UInt64\n\n, e.what() = DB::Exception\n'
2019-01-28 16:18:25,065 - [logs/pythonClickhouse.log:103]=> DATA SUCCESSFULLY LOADED FROM CLICKHOUSE:165863
2019-01-28 16:18:30,310 - [logs/pythonClickhouse.log:103]=> DATA SUCCESSFULLY LOADED FROM CLICKHOUSE:166909
2019-01-28 16:18:31,615 - [logs/pythonClickhouse.log:251]=> insert_df
Traceback (most recent call last):
  File "/home/andre/anaconda3/envs/analytics/lib/python3.5/site-packages/pandahouse/http.py", line 45, in execute
    response.raise_for_status()
  File "/home/andre/anaconda3/envs/analytics/lib/python3.5/site-packages/requests/models.py", line 939, in raise_for_status
    raise HTTPError(http_error_msg, response=self)
requests.exceptions.HTTPError: 500 Server Error: Internal Server Error for url: http://127.0.0.1:8123/?query=INSERT+INTO+%60aion%60.%60network_activity%60+%28%60block_timestamp%60%2C+%60from_addr_new%60%2C+%60from_addr_churned%60%2C+%60from_addr_retained%60%2C+%60from_addr_active%60%2C+%60from_addr_new_lst%60%2C+%60from_addr_churned_lst%60%2C+%60from_addr_retained_lst%60%2C+%60from_addr_active_lst%60%2C+%60to_addr_new_lst%60%2C+%60to_addr_churned_lst%60%2C+%60to_addr_retained_lst%60%2C+%60to_addr_active_lst%60%2C+%60to_addr_new%60%2C+%60to_addr_churned%60%2C+%60to_addr_retained%60%2C+%60to_addr_active%60%2C+%60block_size%60%2C+%60block_time%60%2C+%60difficulty%60%2C+%60nrg_limit%60%2C+%60approx_nrg_reward%60%2C+%60num_transactions%60%2C+%60block_nrg_consumed%60%2C+%60nrg_price%60%2C+%60approx_value%60%2C+%60transaction_nrg_consumed%60%2C+%60block_year%60%2C+%60block_month%60%2C+%60block_day%60%2C+%60day_of_week%60%29+FORMAT+CSV

During handling of the above exception, another exception occurred:

Traceback (most recent call last):
  File "/home/andre/aion/data_science/bokeh/mysql_clickhouse_streamer/scripts/storage/pythonClickhouse.py", line 248, in insert_df
    affected_rows = pandahouse.to_clickhouse(df, table=table, connection=self.conn, index=False)
  File "/home/andre/anaconda3/envs/analytics/lib/python3.5/site-packages/pandahouse/core.py", line 64, in to_clickhouse
    execute(query, data=to_csv(chunk), connection=connection)
  File "/home/andre/anaconda3/envs/analytics/lib/python3.5/site-packages/pandahouse/http.py", line 48, in execute
    raise ClickhouseException(response.content)
pandahouse.http.ClickhouseException: b'Code: 27, e.displayText() = DB::Exception: Cannot parse input: expected " before: a07568b330477453e489a37dc0ca5a29d09f10fd987d056096c790942c543360,a0ef10e5c17bddb4cfa77af683a6466ee72e6ce072ef4847eac863f44402b45f,a05aea454662f9f2e6e10499474042: (at row 1)\n\nRow 1:\nColumn 0,   name: block_timestamp,          type: Date,    parsed text: "<DOUBLE QUOTE>2018-05-16<DOUBLE QUOTE>"\nColumn 1,   name: from_addr_new,            type: UInt64,  ERROR: text "<DOUBLE QUOTE>a07568b33" is not like UInt64\n\n, e.what() = DB::Exception\n'
2019-01-28 16:18:34,961 - [logs/pythonClickhouse.log:103]=> DATA SUCCESSFULLY LOADED FROM CLICKHOUSE:167356
2019-01-28 16:18:40,723 - [logs/pythonClickhouse.log:103]=> DATA SUCCESSFULLY LOADED FROM CLICKHOUSE:157659
2019-01-28 16:18:42,288 - [logs/pythonClickhouse.log:251]=> insert_df
Traceback (most recent call last):
  File "/home/andre/anaconda3/envs/analytics/lib/python3.5/site-packages/pandahouse/http.py", line 45, in execute
    response.raise_for_status()
  File "/home/andre/anaconda3/envs/analytics/lib/python3.5/site-packages/requests/models.py", line 939, in raise_for_status
    raise HTTPError(http_error_msg, response=self)
requests.exceptions.HTTPError: 500 Server Error: Internal Server Error for url: http://127.0.0.1:8123/?query=INSERT+INTO+%60aion%60.%60network_activity%60+%28%60block_timestamp%60%2C+%60from_addr_new%60%2C+%60from_addr_churned%60%2C+%60from_addr_retained%60%2C+%60from_addr_active%60%2C+%60from_addr_new_lst%60%2C+%60from_addr_churned_lst%60%2C+%60from_addr_retained_lst%60%2C+%60from_addr_active_lst%60%2C+%60to_addr_new_lst%60%2C+%60to_addr_churned_lst%60%2C+%60to_addr_retained_lst%60%2C+%60to_addr_active_lst%60%2C+%60to_addr_new%60%2C+%60to_addr_churned%60%2C+%60to_addr_retained%60%2C+%60to_addr_active%60%2C+%60block_size%60%2C+%60block_time%60%2C+%60difficulty%60%2C+%60nrg_limit%60%2C+%60approx_nrg_reward%60%2C+%60num_transactions%60%2C+%60block_nrg_consumed%60%2C+%60nrg_price%60%2C+%60approx_value%60%2C+%60transaction_nrg_consumed%60%2C+%60block_year%60%2C+%60block_month%60%2C+%60block_day%60%2C+%60day_of_week%60%29+FORMAT+CSV

During handling of the above exception, another exception occurred:

Traceback (most recent call last):
  File "/home/andre/aion/data_science/bokeh/mysql_clickhouse_streamer/scripts/storage/pythonClickhouse.py", line 248, in insert_df
    affected_rows = pandahouse.to_clickhouse(df, table=table, connection=self.conn, index=False)
  File "/home/andre/anaconda3/envs/analytics/lib/python3.5/site-packages/pandahouse/core.py", line 64, in to_clickhouse
    execute(query, data=to_csv(chunk), connection=connection)
  File "/home/andre/anaconda3/envs/analytics/lib/python3.5/site-packages/pandahouse/http.py", line 48, in execute
    raise ClickhouseException(response.content)
pandahouse.http.ClickhouseException: b'Code: 27, e.displayText() = DB::Exception: Cannot parse input: expected " before: a0c86eaedb78a5bacf40f193aafeb94ac3b88839c06f9739a6872df1577b135c,a0c6cff5a0182bfcaf0e6dc21a33cce30b14e23451c55cde96ea7f386cea80ed,a07b006c0ef9d8744ca2496e7ba23b: (at row 1)\n\nRow 1:\nColumn 0,   name: block_timestamp,          type: Date,    parsed text: "<DOUBLE QUOTE>2018-05-18<DOUBLE QUOTE>"\nColumn 1,   name: from_addr_new,            type: UInt64,  ERROR: text "<DOUBLE QUOTE>a0c86eaed" is not like UInt64\n\n, e.what() = DB::Exception\n'
2019-01-28 16:18:45,521 - [logs/pythonClickhouse.log:103]=> DATA SUCCESSFULLY LOADED FROM CLICKHOUSE:158981
2019-01-28 16:18:49,579 - [logs/pythonClickhouse.log:103]=> DATA SUCCESSFULLY LOADED FROM CLICKHOUSE:159824
2019-01-28 16:18:50,872 - [logs/pythonClickhouse.log:251]=> insert_df
Traceback (most recent call last):
  File "/home/andre/anaconda3/envs/analytics/lib/python3.5/site-packages/pandahouse/http.py", line 45, in execute
    response.raise_for_status()
  File "/home/andre/anaconda3/envs/analytics/lib/python3.5/site-packages/requests/models.py", line 939, in raise_for_status
    raise HTTPError(http_error_msg, response=self)
requests.exceptions.HTTPError: 500 Server Error: Internal Server Error for url: http://127.0.0.1:8123/?query=INSERT+INTO+%60aion%60.%60network_activity%60+%28%60block_timestamp%60%2C+%60from_addr_new%60%2C+%60from_addr_churned%60%2C+%60from_addr_retained%60%2C+%60from_addr_active%60%2C+%60from_addr_new_lst%60%2C+%60from_addr_churned_lst%60%2C+%60from_addr_retained_lst%60%2C+%60from_addr_active_lst%60%2C+%60to_addr_new_lst%60%2C+%60to_addr_churned_lst%60%2C+%60to_addr_retained_lst%60%2C+%60to_addr_active_lst%60%2C+%60to_addr_new%60%2C+%60to_addr_churned%60%2C+%60to_addr_retained%60%2C+%60to_addr_active%60%2C+%60block_size%60%2C+%60block_time%60%2C+%60difficulty%60%2C+%60nrg_limit%60%2C+%60approx_nrg_reward%60%2C+%60num_transactions%60%2C+%60block_nrg_consumed%60%2C+%60nrg_price%60%2C+%60approx_value%60%2C+%60transaction_nrg_consumed%60%2C+%60block_year%60%2C+%60block_month%60%2C+%60block_day%60%2C+%60day_of_week%60%29+FORMAT+CSV

During handling of the above exception, another exception occurred:

Traceback (most recent call last):
  File "/home/andre/aion/data_science/bokeh/mysql_clickhouse_streamer/scripts/storage/pythonClickhouse.py", line 248, in insert_df
    affected_rows = pandahouse.to_clickhouse(df, table=table, connection=self.conn, index=False)
  File "/home/andre/anaconda3/envs/analytics/lib/python3.5/site-packages/pandahouse/core.py", line 64, in to_clickhouse
    execute(query, data=to_csv(chunk), connection=connection)
  File "/home/andre/anaconda3/envs/analytics/lib/python3.5/site-packages/pandahouse/http.py", line 48, in execute
    raise ClickhouseException(response.content)
pandahouse.http.ClickhouseException: b'Code: 27, e.displayText() = DB::Exception: Cannot parse input: expected " before: a0c6cff5a0182bfcaf0e6dc21a33cce30b14e23451c55cde96ea7f386cea80ed,a07568b330477453e489a37dc0ca5a29d09f10fd987d056096c790942c543360,a0f58035f143b012ee6b937fea48fb: (at row 1)\n\nRow 1:\nColumn 0,   name: block_timestamp,          type: Date,    parsed text: "<DOUBLE QUOTE>2018-05-20<DOUBLE QUOTE>"\nColumn 1,   name: from_addr_new,            type: UInt64,  ERROR: text "<DOUBLE QUOTE>a0c6cff5a" is not like UInt64\n\n, e.what() = DB::Exception\n'
2019-01-28 16:18:53,881 - [logs/pythonClickhouse.log:103]=> DATA SUCCESSFULLY LOADED FROM CLICKHOUSE:160452
2019-01-28 16:18:57,897 - [logs/pythonClickhouse.log:103]=> DATA SUCCESSFULLY LOADED FROM CLICKHOUSE:160794
2019-01-28 16:18:59,048 - [logs/pythonClickhouse.log:251]=> insert_df
Traceback (most recent call last):
  File "/home/andre/anaconda3/envs/analytics/lib/python3.5/site-packages/pandahouse/http.py", line 45, in execute
    response.raise_for_status()
  File "/home/andre/anaconda3/envs/analytics/lib/python3.5/site-packages/requests/models.py", line 939, in raise_for_status
    raise HTTPError(http_error_msg, response=self)
requests.exceptions.HTTPError: 500 Server Error: Internal Server Error for url: http://127.0.0.1:8123/?query=INSERT+INTO+%60aion%60.%60network_activity%60+%28%60block_timestamp%60%2C+%60from_addr_new%60%2C+%60from_addr_churned%60%2C+%60from_addr_retained%60%2C+%60from_addr_active%60%2C+%60from_addr_new_lst%60%2C+%60from_addr_churned_lst%60%2C+%60from_addr_retained_lst%60%2C+%60from_addr_active_lst%60%2C+%60to_addr_new_lst%60%2C+%60to_addr_churned_lst%60%2C+%60to_addr_retained_lst%60%2C+%60to_addr_active_lst%60%2C+%60to_addr_new%60%2C+%60to_addr_churned%60%2C+%60to_addr_retained%60%2C+%60to_addr_active%60%2C+%60block_size%60%2C+%60block_time%60%2C+%60difficulty%60%2C+%60nrg_limit%60%2C+%60approx_nrg_reward%60%2C+%60num_transactions%60%2C+%60block_nrg_consumed%60%2C+%60nrg_price%60%2C+%60approx_value%60%2C+%60transaction_nrg_consumed%60%2C+%60block_year%60%2C+%60block_month%60%2C+%60block_day%60%2C+%60day_of_week%60%29+FORMAT+CSV

During handling of the above exception, another exception occurred:

Traceback (most recent call last):
  File "/home/andre/aion/data_science/bokeh/mysql_clickhouse_streamer/scripts/storage/pythonClickhouse.py", line 248, in insert_df
    affected_rows = pandahouse.to_clickhouse(df, table=table, connection=self.conn, index=False)
  File "/home/andre/anaconda3/envs/analytics/lib/python3.5/site-packages/pandahouse/core.py", line 64, in to_clickhouse
    execute(query, data=to_csv(chunk), connection=connection)
  File "/home/andre/anaconda3/envs/analytics/lib/python3.5/site-packages/pandahouse/http.py", line 48, in execute
    raise ClickhouseException(response.content)
pandahouse.http.ClickhouseException: b'Code: 27, e.displayText() = DB::Exception: Cannot parse input: expected " before: a08507198549743a1c005a69c6e7d9a4e110fe3d1b0110562d7b67c328b4d8cd,a0c6cff5a0182bfcaf0e6dc21a33cce30b14e23451c55cde96ea7f386cea80ed,a07b006c0ef9d8744ca2496e7ba23b: (at row 1)\n\nRow 1:\nColumn 0,   name: block_timestamp,          type: Date,    parsed text: "<DOUBLE QUOTE>2018-05-22<DOUBLE QUOTE>"\nColumn 1,   name: from_addr_new,            type: UInt64,  ERROR: text "<DOUBLE QUOTE>a08507198" is not like UInt64\n\n, e.what() = DB::Exception\n'
2019-01-28 16:19:02,097 - [logs/pythonClickhouse.log:103]=> DATA SUCCESSFULLY LOADED FROM CLICKHOUSE:161303
2019-01-28 16:19:08,886 - [logs/pythonClickhouse.log:103]=> DATA SUCCESSFULLY LOADED FROM CLICKHOUSE:162555
2019-01-28 16:19:10,735 - [logs/pythonClickhouse.log:251]=> insert_df
Traceback (most recent call last):
  File "/home/andre/anaconda3/envs/analytics/lib/python3.5/site-packages/pandahouse/http.py", line 45, in execute
    response.raise_for_status()
  File "/home/andre/anaconda3/envs/analytics/lib/python3.5/site-packages/requests/models.py", line 939, in raise_for_status
    raise HTTPError(http_error_msg, response=self)
requests.exceptions.HTTPError: 500 Server Error: Internal Server Error for url: http://127.0.0.1:8123/?query=INSERT+INTO+%60aion%60.%60network_activity%60+%28%60block_timestamp%60%2C+%60from_addr_new%60%2C+%60from_addr_churned%60%2C+%60from_addr_retained%60%2C+%60from_addr_active%60%2C+%60from_addr_new_lst%60%2C+%60from_addr_churned_lst%60%2C+%60from_addr_retained_lst%60%2C+%60from_addr_active_lst%60%2C+%60to_addr_new_lst%60%2C+%60to_addr_churned_lst%60%2C+%60to_addr_retained_lst%60%2C+%60to_addr_active_lst%60%2C+%60to_addr_new%60%2C+%60to_addr_churned%60%2C+%60to_addr_retained%60%2C+%60to_addr_active%60%2C+%60block_size%60%2C+%60block_time%60%2C+%60difficulty%60%2C+%60nrg_limit%60%2C+%60approx_nrg_reward%60%2C+%60num_transactions%60%2C+%60block_nrg_consumed%60%2C+%60nrg_price%60%2C+%60approx_value%60%2C+%60transaction_nrg_consumed%60%2C+%60block_year%60%2C+%60block_month%60%2C+%60block_day%60%2C+%60day_of_week%60%29+FORMAT+CSV

During handling of the above exception, another exception occurred:

Traceback (most recent call last):
  File "/home/andre/aion/data_science/bokeh/mysql_clickhouse_streamer/scripts/storage/pythonClickhouse.py", line 248, in insert_df
    affected_rows = pandahouse.to_clickhouse(df, table=table, connection=self.conn, index=False)
  File "/home/andre/anaconda3/envs/analytics/lib/python3.5/site-packages/pandahouse/core.py", line 64, in to_clickhouse
    execute(query, data=to_csv(chunk), connection=connection)
  File "/home/andre/anaconda3/envs/analytics/lib/python3.5/site-packages/pandahouse/http.py", line 48, in execute
    raise ClickhouseException(response.content)
pandahouse.http.ClickhouseException: b'Code: 27, e.displayText() = DB::Exception: Cannot parse input: expected " before: a08507198549743a1c005a69c6e7d9a4e110fe3d1b0110562d7b67c328b4d8cd,a07568b330477453e489a37dc0ca5a29d09f10fd987d056096c790942c543360,a0ef10e5c17bddb4cfa77af683a646: (at row 1)\n\nRow 1:\nColumn 0,   name: block_timestamp,          type: Date,    parsed text: "<DOUBLE QUOTE>2018-05-24<DOUBLE QUOTE>"\nColumn 1,   name: from_addr_new,            type: UInt64,  ERROR: text "<DOUBLE QUOTE>a08507198" is not like UInt64\n\n, e.what() = DB::Exception\n'
2019-01-28 16:19:15,721 - [logs/pythonClickhouse.log:103]=> DATA SUCCESSFULLY LOADED FROM CLICKHOUSE:164313
2019-01-28 16:19:20,442 - [logs/pythonClickhouse.log:103]=> DATA SUCCESSFULLY LOADED FROM CLICKHOUSE:165786
2019-01-28 16:19:21,522 - [logs/pythonClickhouse.log:251]=> insert_df
Traceback (most recent call last):
  File "/home/andre/anaconda3/envs/analytics/lib/python3.5/site-packages/pandahouse/http.py", line 45, in execute
    response.raise_for_status()
  File "/home/andre/anaconda3/envs/analytics/lib/python3.5/site-packages/requests/models.py", line 939, in raise_for_status
    raise HTTPError(http_error_msg, response=self)
requests.exceptions.HTTPError: 500 Server Error: Internal Server Error for url: http://127.0.0.1:8123/?query=INSERT+INTO+%60aion%60.%60network_activity%60+%28%60block_timestamp%60%2C+%60from_addr_new%60%2C+%60from_addr_churned%60%2C+%60from_addr_retained%60%2C+%60from_addr_active%60%2C+%60from_addr_new_lst%60%2C+%60from_addr_churned_lst%60%2C+%60from_addr_retained_lst%60%2C+%60from_addr_active_lst%60%2C+%60to_addr_new_lst%60%2C+%60to_addr_churned_lst%60%2C+%60to_addr_retained_lst%60%2C+%60to_addr_active_lst%60%2C+%60to_addr_new%60%2C+%60to_addr_churned%60%2C+%60to_addr_retained%60%2C+%60to_addr_active%60%2C+%60block_size%60%2C+%60block_time%60%2C+%60difficulty%60%2C+%60nrg_limit%60%2C+%60approx_nrg_reward%60%2C+%60num_transactions%60%2C+%60block_nrg_consumed%60%2C+%60nrg_price%60%2C+%60approx_value%60%2C+%60transaction_nrg_consumed%60%2C+%60block_year%60%2C+%60block_month%60%2C+%60block_day%60%2C+%60day_of_week%60%29+FORMAT+CSV

During handling of the above exception, another exception occurred:

Traceback (most recent call last):
  File "/home/andre/aion/data_science/bokeh/mysql_clickhouse_streamer/scripts/storage/pythonClickhouse.py", line 248, in insert_df
    affected_rows = pandahouse.to_clickhouse(df, table=table, connection=self.conn, index=False)
  File "/home/andre/anaconda3/envs/analytics/lib/python3.5/site-packages/pandahouse/core.py", line 64, in to_clickhouse
    execute(query, data=to_csv(chunk), connection=connection)
  File "/home/andre/anaconda3/envs/analytics/lib/python3.5/site-packages/pandahouse/http.py", line 48, in execute
    raise ClickhouseException(response.content)
pandahouse.http.ClickhouseException: b'Code: 27, e.displayText() = DB::Exception: Cannot parse input: expected " before: a0bac5c0b3f10e9841b6cf0895dbb99a7f58d40970196bb8371a6bed98b00cc6,a0d15ee26a5c62729d00cf2712b125c10bb4b31f172d088e8b01994f226420be,a07568b330477453e489a37dc0ca5a: (at row 1)\n\nRow 1:\nColumn 0,   name: block_timestamp,          type: Date,    parsed text: "<DOUBLE QUOTE>2018-05-26<DOUBLE QUOTE>"\nColumn 1,   name: from_addr_new,            type: UInt64,  ERROR: text "<DOUBLE QUOTE>a0bac5c0b" is not like UInt64\n\n, e.what() = DB::Exception\n'
2019-01-28 16:19:26,197 - [logs/pythonClickhouse.log:17]=> logs/pythonClickhouse.log
2019-01-28 16:19:30,702 - [logs/pythonClickhouse.log:103]=> DATA SUCCESSFULLY LOADED FROM CLICKHOUSE:208699
2019-01-28 16:19:36,147 - [logs/pythonClickhouse.log:103]=> DATA SUCCESSFULLY LOADED FROM CLICKHOUSE:211752
2019-01-28 16:19:37,722 - [logs/pythonClickhouse.log:251]=> insert_df
Traceback (most recent call last):
  File "/home/andre/anaconda3/envs/analytics/lib/python3.5/site-packages/pandahouse/http.py", line 45, in execute
    response.raise_for_status()
  File "/home/andre/anaconda3/envs/analytics/lib/python3.5/site-packages/requests/models.py", line 939, in raise_for_status
    raise HTTPError(http_error_msg, response=self)
requests.exceptions.HTTPError: 500 Server Error: Internal Server Error for url: http://127.0.0.1:8123/?query=INSERT+INTO+%60aion%60.%60network_activity%60+%28%60block_timestamp%60%2C+%60from_addr_new%60%2C+%60from_addr_churned%60%2C+%60from_addr_retained%60%2C+%60from_addr_active%60%2C+%60from_addr_new_lst%60%2C+%60from_addr_churned_lst%60%2C+%60from_addr_retained_lst%60%2C+%60from_addr_active_lst%60%2C+%60to_addr_new_lst%60%2C+%60to_addr_churned_lst%60%2C+%60to_addr_retained_lst%60%2C+%60to_addr_active_lst%60%2C+%60to_addr_new%60%2C+%60to_addr_churned%60%2C+%60to_addr_retained%60%2C+%60to_addr_active%60%2C+%60block_size%60%2C+%60block_time%60%2C+%60difficulty%60%2C+%60nrg_limit%60%2C+%60approx_nrg_reward%60%2C+%60num_transactions%60%2C+%60block_nrg_consumed%60%2C+%60nrg_price%60%2C+%60approx_value%60%2C+%60transaction_nrg_consumed%60%2C+%60block_year%60%2C+%60block_month%60%2C+%60block_day%60%2C+%60day_of_week%60%29+FORMAT+CSV

During handling of the above exception, another exception occurred:

Traceback (most recent call last):
  File "/home/andre/aion/data_science/bokeh/mysql_clickhouse_streamer/scripts/storage/pythonClickhouse.py", line 248, in insert_df
    affected_rows = pandahouse.to_clickhouse(df, table=table, connection=self.conn, index=False)
  File "/home/andre/anaconda3/envs/analytics/lib/python3.5/site-packages/pandahouse/core.py", line 64, in to_clickhouse
    execute(query, data=to_csv(chunk), connection=connection)
  File "/home/andre/anaconda3/envs/analytics/lib/python3.5/site-packages/pandahouse/http.py", line 48, in execute
    raise ClickhouseException(response.content)
pandahouse.http.ClickhouseException: b'Code: 27, e.displayText() = DB::Exception: Cannot parse input: expected " before: a0a5ecf0ead1fd01092bbac788368c72ee4dde410e82c6e61a89b0b5c7b2791b,a0460659ac0fb42e19590b1ed27bd8835e97392417fa8d6d5fcd02015fcf36a3,a00339fa21a77726f9635de520778f: (at row 1)\n\nRow 1:\nColumn 0,   name: block_timestamp,          type: Date,    parsed text: "<DOUBLE QUOTE>2018-05-02<DOUBLE QUOTE>"\nColumn 1,   name: from_addr_new,            type: UInt64,  ERROR: text "<DOUBLE QUOTE>a0a5ecf0e" is not like UInt64\n\n, e.what() = DB::Exception\n'
2019-01-28 16:19:42,401 - [logs/pythonClickhouse.log:103]=> DATA SUCCESSFULLY LOADED FROM CLICKHOUSE:201886
2019-01-28 16:19:47,573 - [logs/pythonClickhouse.log:103]=> DATA SUCCESSFULLY LOADED FROM CLICKHOUSE:202069
2019-01-28 16:19:48,916 - [logs/pythonClickhouse.log:251]=> insert_df
Traceback (most recent call last):
  File "/home/andre/anaconda3/envs/analytics/lib/python3.5/site-packages/pandahouse/http.py", line 45, in execute
    response.raise_for_status()
  File "/home/andre/anaconda3/envs/analytics/lib/python3.5/site-packages/requests/models.py", line 939, in raise_for_status
    raise HTTPError(http_error_msg, response=self)
requests.exceptions.HTTPError: 500 Server Error: Internal Server Error for url: http://127.0.0.1:8123/?query=INSERT+INTO+%60aion%60.%60network_activity%60+%28%60block_timestamp%60%2C+%60from_addr_new%60%2C+%60from_addr_churned%60%2C+%60from_addr_retained%60%2C+%60from_addr_active%60%2C+%60from_addr_new_lst%60%2C+%60from_addr_churned_lst%60%2C+%60from_addr_retained_lst%60%2C+%60from_addr_active_lst%60%2C+%60to_addr_new_lst%60%2C+%60to_addr_churned_lst%60%2C+%60to_addr_retained_lst%60%2C+%60to_addr_active_lst%60%2C+%60to_addr_new%60%2C+%60to_addr_churned%60%2C+%60to_addr_retained%60%2C+%60to_addr_active%60%2C+%60block_size%60%2C+%60block_time%60%2C+%60difficulty%60%2C+%60nrg_limit%60%2C+%60approx_nrg_reward%60%2C+%60num_transactions%60%2C+%60block_nrg_consumed%60%2C+%60nrg_price%60%2C+%60approx_value%60%2C+%60transaction_nrg_consumed%60%2C+%60block_year%60%2C+%60block_month%60%2C+%60block_day%60%2C+%60day_of_week%60%29+FORMAT+CSV

During handling of the above exception, another exception occurred:

Traceback (most recent call last):
  File "/home/andre/aion/data_science/bokeh/mysql_clickhouse_streamer/scripts/storage/pythonClickhouse.py", line 248, in insert_df
    affected_rows = pandahouse.to_clickhouse(df, table=table, connection=self.conn, index=False)
  File "/home/andre/anaconda3/envs/analytics/lib/python3.5/site-packages/pandahouse/core.py", line 64, in to_clickhouse
    execute(query, data=to_csv(chunk), connection=connection)
  File "/home/andre/anaconda3/envs/analytics/lib/python3.5/site-packages/pandahouse/http.py", line 48, in execute
    raise ClickhouseException(response.content)
pandahouse.http.ClickhouseException: b'Code: 27, e.displayText() = DB::Exception: Cannot parse input: expected " before: a04e625e67f21973403b6cc458f79d19e098e05a5540a7054c8f27e2adcbc00e,a07f698e358a96d2c5e188971d57919965333fde138dcd58410d63ba586c9e20,a067d14d13405d1b877ce1a1dd50ae: (at row 1)\n\nRow 1:\nColumn 0,   name: block_timestamp,          type: Date,    parsed text: "<DOUBLE QUOTE>2018-05-04<DOUBLE QUOTE>"\nColumn 1,   name: from_addr_new,            type: UInt64,  ERROR: text "<DOUBLE QUOTE>a04e625e6" is not like UInt64\n\n, e.what() = DB::Exception\n'
2019-01-28 16:19:53,723 - [logs/pythonClickhouse.log:103]=> DATA SUCCESSFULLY LOADED FROM CLICKHOUSE:201936
2019-01-28 16:19:59,656 - [logs/pythonClickhouse.log:103]=> DATA SUCCESSFULLY LOADED FROM CLICKHOUSE:192787
2019-01-28 16:20:00,839 - [logs/pythonClickhouse.log:251]=> insert_df
Traceback (most recent call last):
  File "/home/andre/anaconda3/envs/analytics/lib/python3.5/site-packages/pandahouse/http.py", line 45, in execute
    response.raise_for_status()
  File "/home/andre/anaconda3/envs/analytics/lib/python3.5/site-packages/requests/models.py", line 939, in raise_for_status
    raise HTTPError(http_error_msg, response=self)
requests.exceptions.HTTPError: 500 Server Error: Internal Server Error for url: http://127.0.0.1:8123/?query=INSERT+INTO+%60aion%60.%60network_activity%60+%28%60block_timestamp%60%2C+%60from_addr_new%60%2C+%60from_addr_churned%60%2C+%60from_addr_retained%60%2C+%60from_addr_active%60%2C+%60from_addr_new_lst%60%2C+%60from_addr_churned_lst%60%2C+%60from_addr_retained_lst%60%2C+%60from_addr_active_lst%60%2C+%60to_addr_new_lst%60%2C+%60to_addr_churned_lst%60%2C+%60to_addr_retained_lst%60%2C+%60to_addr_active_lst%60%2C+%60to_addr_new%60%2C+%60to_addr_churned%60%2C+%60to_addr_retained%60%2C+%60to_addr_active%60%2C+%60block_size%60%2C+%60block_time%60%2C+%60difficulty%60%2C+%60nrg_limit%60%2C+%60approx_nrg_reward%60%2C+%60num_transactions%60%2C+%60block_nrg_consumed%60%2C+%60nrg_price%60%2C+%60approx_value%60%2C+%60transaction_nrg_consumed%60%2C+%60block_year%60%2C+%60block_month%60%2C+%60block_day%60%2C+%60day_of_week%60%29+FORMAT+CSV

During handling of the above exception, another exception occurred:

Traceback (most recent call last):
  File "/home/andre/aion/data_science/bokeh/mysql_clickhouse_streamer/scripts/storage/pythonClickhouse.py", line 248, in insert_df
    affected_rows = pandahouse.to_clickhouse(df, table=table, connection=self.conn, index=False)
  File "/home/andre/anaconda3/envs/analytics/lib/python3.5/site-packages/pandahouse/core.py", line 64, in to_clickhouse
    execute(query, data=to_csv(chunk), connection=connection)
  File "/home/andre/anaconda3/envs/analytics/lib/python3.5/site-packages/pandahouse/http.py", line 48, in execute
    raise ClickhouseException(response.content)
pandahouse.http.ClickhouseException: b'Code: 27, e.displayText() = DB::Exception: Cannot parse input: expected " before: a04e625e67f21973403b6cc458f79d19e098e05a5540a7054c8f27e2adcbc00e,a07f698e358a96d2c5e188971d57919965333fde138dcd58410d63ba586c9e20,a067d14d13405d1b877ce1a1dd50ae: (at row 1)\n\nRow 1:\nColumn 0,   name: block_timestamp,          type: Date,    parsed text: "<DOUBLE QUOTE>2018-05-06<DOUBLE QUOTE>"\nColumn 1,   name: from_addr_new,            type: UInt64,  ERROR: text "<DOUBLE QUOTE>a04e625e6" is not like UInt64\n\n, e.what() = DB::Exception\n'
2019-01-28 16:20:05,722 - [logs/pythonClickhouse.log:103]=> DATA SUCCESSFULLY LOADED FROM CLICKHOUSE:192399
2019-01-28 16:26:04,984 - [logs/pythonClickhouse.log:17]=> logs/pythonClickhouse.log
2019-01-28 16:34:07,074 - [logs/pythonClickhouse.log:17]=> logs/pythonClickhouse.log
2019-01-28 16:34:12,074 - [logs/pythonClickhouse.log:103]=> DATA SUCCESSFULLY LOADED FROM CLICKHOUSE:208699
2019-01-28 16:34:18,710 - [logs/pythonClickhouse.log:103]=> DATA SUCCESSFULLY LOADED FROM CLICKHOUSE:211752
2019-01-28 16:34:20,489 - [logs/pythonClickhouse.log:251]=> insert_df
Traceback (most recent call last):
  File "/home/andre/anaconda3/envs/analytics/lib/python3.5/site-packages/pandahouse/http.py", line 45, in execute
    response.raise_for_status()
  File "/home/andre/anaconda3/envs/analytics/lib/python3.5/site-packages/requests/models.py", line 939, in raise_for_status
    raise HTTPError(http_error_msg, response=self)
requests.exceptions.HTTPError: 500 Server Error: Internal Server Error for url: http://127.0.0.1:8123/?query=INSERT+INTO+%60aion%60.%60network_activity%60+%28%60block_timestamp%60%2C+%60from_addr_new%60%2C+%60from_addr_churned%60%2C+%60from_addr_retained%60%2C+%60from_addr_active%60%2C+%60from_addr_new_lst%60%2C+%60from_addr_churned_lst%60%2C+%60from_addr_retained_lst%60%2C+%60from_addr_active_lst%60%2C+%60to_addr_new_lst%60%2C+%60to_addr_churned_lst%60%2C+%60to_addr_retained_lst%60%2C+%60to_addr_active_lst%60%2C+%60to_addr_new%60%2C+%60to_addr_churned%60%2C+%60to_addr_retained%60%2C+%60to_addr_active%60%2C+%60block_size%60%2C+%60block_time%60%2C+%60difficulty%60%2C+%60nrg_limit%60%2C+%60approx_nrg_reward%60%2C+%60num_transactions%60%2C+%60block_nrg_consumed%60%2C+%60nrg_price%60%2C+%60approx_value%60%2C+%60transaction_nrg_consumed%60%2C+%60block_year%60%2C+%60block_month%60%2C+%60block_day%60%2C+%60day_of_week%60%29+FORMAT+CSV

During handling of the above exception, another exception occurred:

Traceback (most recent call last):
  File "/home/andre/aion/data_science/bokeh/mysql_clickhouse_streamer/scripts/storage/pythonClickhouse.py", line 248, in insert_df
    affected_rows = pandahouse.to_clickhouse(df, table=table, connection=self.conn, index=False)
  File "/home/andre/anaconda3/envs/analytics/lib/python3.5/site-packages/pandahouse/core.py", line 64, in to_clickhouse
    execute(query, data=to_csv(chunk), connection=connection)
  File "/home/andre/anaconda3/envs/analytics/lib/python3.5/site-packages/pandahouse/http.py", line 48, in execute
    raise ClickhouseException(response.content)
pandahouse.http.ClickhouseException: b'Code: 27, e.displayText() = DB::Exception: Cannot parse input: expected " before: a0ead4c6661b8e2e3ec5f207d540b0becdb3b43e54ad4999320d6530c4a401b8,a0460659ac0fb42e19590b1ed27bd8835e97392417fa8d6d5fcd02015fcf36a3,a05bcaf3b86728600e31ee50d7654f: (at row 1)\n\nRow 1:\nColumn 0,   name: block_timestamp,          type: Date,    parsed text: "<DOUBLE QUOTE>2018-05-02<DOUBLE QUOTE>"\nColumn 1,   name: from_addr_new,            type: UInt64,  ERROR: text "<DOUBLE QUOTE>a0ead4c66" is not like UInt64\n\n, e.what() = DB::Exception\n'
2019-01-28 16:34:25,377 - [logs/pythonClickhouse.log:103]=> DATA SUCCESSFULLY LOADED FROM CLICKHOUSE:201886
